<sdf version='1.5'>
  <world name='default'>
    <light name='sun' type='directional'>
      <cast_shadows>1</cast_shadows>
      <pose>0 0 10 0 -0 0</pose>
      <diffuse>0.8 0.8 0.8 1</diffuse>
      <specular>0.2 0.2 0.2 1</specular>
      <attenuation>
        <range>1000</range>
        <constant>0.9</constant>
        <linear>0.01</linear>
        <quadratic>0.001</quadratic>
      </attenuation>
      <direction>-0.5 0.1 -0.9</direction>
    </light>
    <model name='ground_plane'>
      <static>1</static>
      <link name='link'>
        <collision name='collision'>
          <geometry>
            <plane>
              <normal>0 0 1</normal>
              <size>100 100</size>
            </plane>
          </geometry>
          <surface>
            <friction>
              <ode>
                <mu>100</mu>
                <mu2>50</mu2>
              </ode>
            </friction>
            <contact>
              <ode/>
            </contact>
            <bounce/>
          </surface>
          <max_contacts>10</max_contacts>
        </collision>
        <visual name='visual'>
          <cast_shadows>0</cast_shadows>
          <geometry>
            <plane>
              <normal>0 0 1</normal>
              <size>100 100</size>
            </plane>
          </geometry>
          <material>
            <script>
              <uri>file://media/materials/scripts/gazebo.material</uri>
              <name>Gazebo/Grey</name>
            </script>
          </material>
        </visual>
        <self_collide>0</self_collide>
        <kinematic>0</kinematic>
        <gravity>1</gravity>
      </link>
    </model>
    <physics name='default_physics' default='0' type='ode'>
      <max_step_size>0.001</max_step_size>
      <real_time_factor>1</real_time_factor>
      <real_time_update_rate>1000</real_time_update_rate>
      <gravity>0 0 -9.8</gravity>
      <magnetic_field>5.5645e-06 2.28758e-05 -4.23884e-05</magnetic_field>
    </physics>
    <scene>
      <ambient>0.4 0.4 0.4 1</ambient>
      <background>0.7 0.7 0.7 1</background>
      <shadows>1</shadows>
    </scene>
    <spherical_coordinates>
      <surface_model>EARTH_WGS84</surface_model>
      <latitude_deg>0</latitude_deg>
      <longitude_deg>0</longitude_deg>
      <elevation>0</elevation>
      <heading_deg>0</heading_deg>
    </spherical_coordinates>
    <model name='unit_box_1'>
      <pose>-2 1.56478 0.5 0 -0 0</pose>
      <link name='link'>
        <inertial>
          <mass>1</mass>
          <inertia>
            <ixx>1</ixx>
            <ixy>0</ixy>
            <ixz>0</ixz>
            <iyy>1</iyy>
            <iyz>0</iyz>
            <izz>1</izz>
          </inertia>
        </inertial>
        <collision name='collision'>
          <geometry>
            <box>
              <size>1 1 1</size>
            </box>
          </geometry>
          <max_contacts>10</max_contacts>
          <surface>
            <contact>
              <ode/>
            </contact>
            <bounce/>
            <friction>
              <ode/>
            </friction>
          </surface>
        </collision>
        <visual name='visual'>
          <geometry>
            <box>
              <size>1 1 1</size>
            </box>
          </geometry>
          <material>
            <script>
              <uri>file://media/materials/scripts/gazebo.material</uri>
              <name>Gazebo/Grey</name>
            </script>
          </material>
        </visual>
        <self_collide>0</self_collide>
        <kinematic>0</kinematic>
        <gravity>1</gravity>
      </link>
    </model>
    <model name='unit_box_2'>
      <pose>0.549139 -1 0.5 0 -0 0</pose>
      <link name='link'>
        <inertial>
          <mass>1</mass>
          <inertia>
            <ixx>1</ixx>
            <ixy>0</ixy>
            <ixz>0</ixz>
            <iyy>1</iyy>
            <iyz>0</iyz>
            <izz>1</izz>
          </inertia>
        </inertial>
        <collision name='collision'>
          <geometry>
            <box>
              <size>1 1 1</size>
            </box>
          </geometry>
          <max_contacts>10</max_contacts>
          <surface>
            <contact>
              <ode/>
            </contact>
            <bounce/>
            <friction>
              <ode/>
            </friction>
          </surface>
        </collision>
        <visual name='visual'>
          <geometry>
            <box>
              <size>1 1 1</size>
            </box>
          </geometry>
          <material>
            <script>
              <uri>file://media/materials/scripts/gazebo.material</uri>
              <name>Gazebo/Grey</name>
            </script>
          </material>
        </visual>
        <self_collide>0</self_collide>
        <kinematic>0</kinematic>
        <gravity>1</gravity>
      </link>
    </model>
    <model name='unit_box_3'>
      <pose>1 1 0.5 0 -0 0</pose>
      <link name='link'>
        <inertial>
          <mass>1</mass>
          <inertia>
            <ixx>1</ixx>
            <ixy>0</ixy>
            <ixz>0</ixz>
            <iyy>1</iyy>
            <iyz>0</iyz>
            <izz>1</izz>
          </inertia>
        </inertial>
        <collision name='collision'>
          <geometry>
            <box>
              <size>1 1 1</size>
            </box>
          </geometry>
          <max_contacts>10</max_contacts>
          <surface>
            <contact>
              <ode/>
            </contact>
            <bounce/>
            <friction>
              <ode/>
            </friction>
          </surface>
        </collision>
        <visual name='visual'>
          <geometry>
            <box>
              <size>1 1 1</size>
            </box>
          </geometry>
          <material>
            <script>
              <uri>file://media/materials/scripts/gazebo.material</uri>
              <name>Gazebo/Grey</name>
            </script>
          </material>
        </visual>
        <self_collide>0</self_collide>
        <kinematic>0</kinematic>
        <gravity>1</gravity>
      </link>
    </model>
    <model name='AMiRo Hokuyo tilted'>
      <static>0</static>
      <static>0</static>
      <link name='AMiRo::chassis'>
        <inertial>
          <mass>0.4</mass>
          <inertia>
            <ixx>0.0012</ixx>
            <ixy>0</ixy>
            <ixz>0</ixz>
            <iyy>0.0012</iyy>
            <iyz>0</iyz>
            <izz>0.005</izz>
          </inertia>
        </inertial>
        <velocity_decay>
          <linear>0</linear>
          <angular>0</angular>
        </velocity_decay>
        <collision name='collision_DiWheelDrive'>
          <pose>0 0 0.011 0 -0 0</pose>
          <geometry>
            <cylinder>
              <radius>0.05</radius>
              <length>0.002</length>
            </cylinder>
          </geometry>
          <max_contacts>10</max_contacts>
          <surface>
            <contact>
              <ode/>
            </contact>
            <bounce/>
            <friction>
              <ode/>
            </friction>
          </surface>
        </collision>
        <visual name='visual_DiWheelDrive'>
          <pose>0 0 0.011 0 -0 0</pose>
          <geometry>
            <cylinder>
              <radius>0.05</radius>
              <length>0.002</length>
            </cylinder>
          </geometry>
        </visual>
        <collision name='collision_SensorRing'>
          <pose>0 0 0.037 0 -0 0</pose>
          <geometry>
            <cylinder>
              <radius>0.05</radius>
              <length>0.051</length>
            </cylinder>
          </geometry>
          <max_contacts>10</max_contacts>
          <surface>
            <contact>
              <ode/>
            </contact>
            <bounce/>
            <friction>
              <ode/>
            </friction>
          </surface>
        </collision>
        <visual name='visual_SensorRing'>
          <pose>0 0 0.037 0 -0 0</pose>
          <geometry>
            <cylinder>
              <radius>0.05</radius>
              <length>0.051</length>
            </cylinder>
          </geometry>
        </visual>
        <collision name='collision_Hat'>
          <pose>0 0 0.073 0 -0 0</pose>
          <geometry>
            <cylinder>
              <radius>0.05</radius>
              <length>0.02</length>
            </cylinder>
          </geometry>
          <max_contacts>10</max_contacts>
          <surface>
            <contact>
              <ode/>
            </contact>
            <bounce/>
            <friction>
              <ode/>
            </friction>
          </surface>
        </collision>
        <visual name='visual_Hat'>
          <pose>0 0 0.073 0 -0 0</pose>
          <geometry>
            <cylinder>
              <radius>0.05</radius>
              <length>0.02</length>
            </cylinder>
          </geometry>
        </visual>
        <collision name='collision_sph_caster_front'>
          <pose>0.042 0 0.0025 0 -0 0</pose>
          <laser_retro>0</laser_retro>
          <geometry>
            <sphere>
              <radius>0.002</radius>
            </sphere>
          </geometry>
          <surface>
            <friction>
              <ode>
                <mu>0.01</mu>
                <mu2>0.01</mu2>
                <fdir1>0 0 0</fdir1>
                <slip1>0</slip1>
                <slip2>0</slip2>
              </ode>
            </friction>
            <bounce>
              <restitution_coefficient>0</restitution_coefficient>
              <threshold>100000</threshold>
            </bounce>
            <contact>
              <ode>
                <soft_cfm>0</soft_cfm>
                <soft_erp>0.2</soft_erp>
                <kp>1e+12</kp>
                <kd>1</kd>
                <max_vel>100</max_vel>
                <min_depth>0.001</min_depth>
              </ode>
            </contact>
          </surface>
          <max_contacts>10</max_contacts>
        </collision>
        <visual name='visual_sph_caster_front'>
          <pose>0.042 0 0.0025 0 -0 0</pose>
          <geometry>
            <sphere>
              <radius>0.002</radius>
            </sphere>
          </geometry>
        </visual>
        <collision name='collision_cyl_caster_front'>
          <pose>0.042 0 0.0065 0 -0 0</pose>
          <geometry>
            <cylinder>
              <radius>0.003</radius>
              <length>0.007</length>
            </cylinder>
          </geometry>
          <surface>
            <friction>
              <ode>
                <mu>0</mu>
                <mu2>0</mu2>
              </ode>
              <bullet>
                <friction>0</friction>
                <friction2>0</friction2>
              </bullet>
            </friction>
            <contact>
              <collide_without_contact>0</collide_without_contact>
              <ode/>
            </contact>
            <bounce/>
          </surface>
          <max_contacts>10</max_contacts>
        </collision>
        <visual name='visual_cyl_caster_front'>
          <pose>0.042 0 0.0065 0 -0 0</pose>
          <geometry>
            <cylinder>
              <radius>0.003</radius>
              <length>0.007</length>
            </cylinder>
          </geometry>
        </visual>
        <collision name='collision_sph_caster_back'>
          <pose>-0.042 0 0.0025 0 -0 0</pose>
          <geometry>
            <sphere>
              <radius>0.002</radius>
            </sphere>
          </geometry>
          <surface>
            <friction>
              <ode>
                <mu>0.01</mu>
                <mu2>0.01</mu2>
                <fdir1>0 0 0</fdir1>
                <slip1>0</slip1>
                <slip2>0</slip2>
              </ode>
            </friction>
            <bounce>
              <restitution_coefficient>0</restitution_coefficient>
              <threshold>100000</threshold>
            </bounce>
            <contact>
              <ode>
                <soft_cfm>0</soft_cfm>
                <soft_erp>0.2</soft_erp>
                <kp>1e+12</kp>
                <kd>1</kd>
                <max_vel>100</max_vel>
                <min_depth>0.001</min_depth>
              </ode>
            </contact>
          </surface>
          <max_contacts>10</max_contacts>
        </collision>
        <visual name='visual_sph_caster_back'>
          <pose>-0.042 0 0.0025 0 -0 0</pose>
          <geometry>
            <sphere>
              <radius>0.002</radius>
            </sphere>
          </geometry>
        </visual>
        <collision name='collision_cyl_caster_back'>
          <pose>-0.042 0 0.0065 0 -0 0</pose>
          <geometry>
            <cylinder>
              <radius>0.003</radius>
              <length>0.007</length>
            </cylinder>
          </geometry>
          <max_contacts>10</max_contacts>
          <surface>
            <contact>
              <ode/>
            </contact>
            <bounce/>
            <friction>
              <ode/>
            </friction>
          </surface>
        </collision>
        <visual name='visual_cyl_caster_back'>
          <pose>-0.042 0 0.0065 0 -0 0</pose>
          <geometry>
            <cylinder>
              <radius>0.003</radius>
              <length>0.007</length>
            </cylinder>
          </geometry>
        </visual>
        <pose>0 0 0 0 -0 0</pose>
        <self_collide>0</self_collide>
        <kinematic>0</kinematic>
        <gravity>1</gravity>
      </link>
      <link name='AMiRo::left_wheel'>
        <pose>0 0.035 0.03 -5.76279e-13 1.5707 1.5707</pose>
        <inertial>
          <mass>0.02</mass>
          <inertia>
            <ixx>6.8453e-06</ixx>
            <ixy>0</ixy>
            <ixz>0</ixz>
            <iyy>6.8453e-06</iyy>
            <iyz>0</iyz>
            <izz>7.5625e-06</izz>
          </inertia>
        </inertial>
        <collision name='collision'>
          <geometry>
            <cylinder>
              <radius>0.03</radius>
              <length>0.006</length>
            </cylinder>
          </geometry>
          <max_contacts>10</max_contacts>
          <surface>
            <contact>
              <ode/>
            </contact>
            <bounce/>
            <friction>
              <ode/>
            </friction>
          </surface>
        </collision>
        <visual name='visual'>
          <geometry>
            <cylinder>
              <radius>0.03</radius>
              <length>0.006</length>
            </cylinder>
          </geometry>
        </visual>
        <self_collide>0</self_collide>
        <kinematic>0</kinematic>
        <gravity>1</gravity>
      </link>
      <link name='AMiRo::right_wheel'>
        <pose>0 -0.035 0.03 -5.76279e-13 1.5707 1.5707</pose>
        <inertial>
          <mass>0.02</mass>
          <inertia>
            <ixx>6.8453e-06</ixx>
            <ixy>0</ixy>
            <ixz>0</ixz>
            <iyy>6.8453e-06</iyy>
            <iyz>0</iyz>
            <izz>7.5625e-06</izz>
          </inertia>
        </inertial>
        <collision name='collision'>
          <geometry>
            <cylinder>
              <radius>0.03</radius>
              <length>0.006</length>
            </cylinder>
          </geometry>
          <max_contacts>10</max_contacts>
          <surface>
            <contact>
              <ode/>
            </contact>
            <bounce/>
            <friction>
              <ode/>
            </friction>
          </surface>
        </collision>
        <visual name='visual'>
          <geometry>
            <cylinder>
              <radius>0.03</radius>
              <length>0.006</length>
            </cylinder>
          </geometry>
        </visual>
        <self_collide>0</self_collide>
        <kinematic>0</kinematic>
        <gravity>1</gravity>
      </link>
      <joint name='AMiRo::left_wheel_hinge' type='revolute'>
        <pose>0 0 0 0 -0 0</pose>
        <child>AMiRo::left_wheel</child>
        <parent>AMiRo::chassis</parent>
        <axis>
          <xyz>0 1 0</xyz>
          <use_parent_model_frame>1</use_parent_model_frame>
          <limit>
            <lower>-1e+16</lower>
            <upper>1e+16</upper>
          </limit>
          <dynamics>
            <spring_reference>0</spring_reference>
            <spring_stiffness>0</spring_stiffness>
          </dynamics>
        </axis>
      </joint>
      <joint name='AMiRo::right_wheel_hinge' type='revolute'>
        <pose>0 0 0 0 -0 0</pose>
        <child>AMiRo::right_wheel</child>
        <parent>AMiRo::chassis</parent>
        <axis>
          <xyz>0 1 0</xyz>
          <use_parent_model_frame>1</use_parent_model_frame>
          <limit>
            <lower>-1e+16</lower>
            <upper>1e+16</upper>
          </limit>
          <dynamics>
            <spring_reference>0</spring_reference>
            <spring_stiffness>0</spring_stiffness>
          </dynamics>
        </axis>
      </joint>
      <plugin name='model_push' filename='libgazebo_rsb_wheel.so'>
        <differentialKinematicSubscope>diffKin</differentialKinematicSubscope>
        <baseWidth>0.06</baseWidth>
        <wheelRadius>0.03</wheelRadius>
        <rightWheelMaxForceN>2.4</rightWheelMaxForceN>
        <leftWheelMaxForceN>2.4</leftWheelMaxForceN>
      </plugin>
      <link name='AMiRo::gps'>
        <sensor name='positioning' type='AMiRo::gps'>
          <pose>0 0 0 0 -0 0</pose>
          <always_on>1</always_on>
          <update_rate>10</update_rate>
          <visualize>1</visualize>
        </sensor>
        <pose>0 0 0 0 -0 0</pose>
        <self_collide>0</self_collide>
        <inertial>
          <inertia>
            <ixx>1</ixx>
            <ixy>0</ixy>
            <ixz>0</ixz>
            <iyy>1</iyy>
            <iyz>0</iyz>
            <izz>1</izz>
          </inertia>
          <mass>1</mass>
        </inertial>
        <kinematic>0</kinematic>
        <gravity>1</gravity>
      </link>
      <plugin name='positioning' filename='libgazebo_rsb_gps.so'>
        <alwaysOn>true</alwaysOn>
        <updateRate>10.0</updateRate>
        <gpsSubscope>AMiRo::gps</gpsSubscope>
      </plugin>
      <plugin name='odometry' filename='libgazebo_rsb_odom_amiro.so'>
        <alwaysOn>true</alwaysOn>
        <updateRate>10.0</updateRate>
        <odomSubscope>odom</odomSubscope>
        <baseWidth>0.055</baseWidth>
        <kl>0.01</kl>
        <kr>0.01</kr>
      </plugin>
      <link name='hokuyo::link'>
        <inertial>
          <mass>0.1</mass>
          <inertia>
            <ixx>4.56e-05</ixx>
            <ixy>0</ixy>
            <ixz>0</ixz>
            <iyy>4.56e-05</iyy>
            <iyz>0</iyz>
            <izz>3.12e-05</izz>
          </inertia>
        </inertial>
        <visual name='visual'>
          <geometry>
            <mesh>
              <uri>model://hokuyo/meshes/hokuyo.dae</uri>
            </mesh>
          </geometry>
        </visual>
        <collision name='collision-base'>
          <pose>0 0 -0.0145 0 -0 0</pose>
          <geometry>
            <box>
              <size>0.05 0.05 0.041</size>
            </box>
          </geometry>
          <max_contacts>10</max_contacts>
          <surface>
            <contact>
              <ode/>
            </contact>
            <bounce/>
            <friction>
              <ode/>
            </friction>
          </surface>
        </collision>
        <collision name='collision-top'>
          <pose>0 0 0.0205 0 -0 0</pose>
          <geometry>
            <cylinder>
              <radius>0.021</radius>
              <length>0.029</length>
            </cylinder>
          </geometry>
          <max_contacts>10</max_contacts>
          <surface>
            <contact>
              <ode/>
            </contact>
            <bounce/>
            <friction>
              <ode/>
            </friction>
          </surface>
        </collision>
        <sensor name='laser' type='ray'>
          <pose>0.01 0 0.0175 0 -0 0</pose>
          <ray>
            <scan>
              <horizontal>
                <samples>91</samples>
                <resolution>1</resolution>
                <min_angle>-0.785</min_angle>
                <max_angle>0.785</max_angle>
              </horizontal>
            </scan>
            <range>
              <min>0.08</min>
              <max>5</max>
              <resolution>0.01</resolution>
            </range>
          </ray>
          <plugin name='laser' filename='libgazebo_rsb_laser.so'>
            <lidarSubscope>lidar</lidarSubscope>
          </plugin>
          <always_on>1</always_on>
          <update_rate>10</update_rate>
          <visualize>1</visualize>
        </sensor>
        <pose>0 0 0.125 0 0.5234 0</pose>
        <self_collide>0</self_collide>
        <kinematic>0</kinematic>
        <gravity>1</gravity>
      </link>
      <joint name='hokuyo_joint' type='revolute'>
        <child>hokuyo::link</child>
        <parent>AMiRo::chassis</parent>
        <axis>
          <xyz>0 0 1</xyz>
          <limit>
            <upper>0</upper>
            <lower>0</lower>
          </limit>
          <use_parent_model_frame>1</use_parent_model_frame>
          <dynamics>
            <spring_reference>0</spring_reference>
            <spring_stiffness>0</spring_stiffness>
          </dynamics>
        </axis>
      </joint>
      <pose>0 0.41785 0 0 -0 0</pose>
    </model>
    <state world_name='default'>
      <sim_time>76 427000000</sim_time>
      <real_time>78 424075404</real_time>
      <wall_time>1429366918 551261510</wall_time>
      <model name='AMiRo Hokuyo tilted'>
        <pose>1.1e-05 0.420929 0 1.5e-05 1e-06 0.000108</pose>
        <link name='AMiRo::chassis'>
          <pose>1.1e-05 0.420929 0 1.5e-05 1e-06 0.000108</pose>
          <velocity>0 -0.001085 0.001745 -0.030406 -9e-06 -3.3e-05</velocity>
          <acceleration>-9e-05 -1.42806 3.38022 -0.209291 -1.7e-05 -0.001023</acceleration>
          <wrench>-3.6e-05 -0.571226 1.35209 0 -0 0</wrench>
        </link>
        <link name='AMiRo::gps'>
          <pose>0 0.41785 -3806.69 0 -0 0</pose>
          <velocity>0 0 -273.146 0 -0 0</velocity>
          <acceleration>0 0 -9.8 0 -0 0</acceleration>
          <wrench>0 0 -9.8 0 -0 0</wrench>
        </link>
        <link name='AMiRo::left_wheel'>
          <pose>8e-06 0.455927 0.03 -1.46582 1.57072 0.104987</pose>
          <velocity>1e-06 4.7e-05 8.3e-05 -0.00158 2.5e-05 -3e-05</velocity>
          <acceleration>0.001701 0.996645 0.115649 -0.011603 2e-05 -2.8e-05</acceleration>
          <wrench>3.4e-05 0.019933 0.002313 0 -0 0</wrench>
        </link>
        <link name='AMiRo::right_wheel'>
          <pose>1.5e-05 0.385929 0.030001 -0.489439 1.57059 1.08137</pose>
          <velocity>-1e-06 0.000134 0.003298 -0.005258 -3e-05 -3.1e-05</velocity>
          <acceleration>-0.002852 1.11272 6.47839 -0.011119 -9e-06 -3e-05</acceleration>
          <wrench>-5.7e-05 0.022254 0.129568 0 -0 0</wrench>
        </link>
        <link name='hokuyo::link'>
          <pose>1.2e-05 0.420927 0.125 1.9e-05 0.523401 0.000117</pose>
          <velocity>-1e-06 0.002637 0.001751 -0.029704 -9e-06 -0.000112</velocity>
          <acceleration>-0.000779 7.17793 3.38994 -0.031353 -2e-06 -9.8e-05</acceleration>
          <wrench>-7.8e-05 0.717793 0.338994 0 -0 0</wrench>
        </link>
      </model>
      <model name='ground_plane'>
        <pose>0 0 0 0 -0 0</pose>
        <link name='link'>
          <pose>0 0 0 0 -0 0</pose>
          <velocity>0 0 0 0 -0 0</velocity>
          <acceleration>0 0 0 0 -0 0</acceleration>
          <wrench>0 0 0 0 -0 0</wrench>
        </link>
      </model>
      <model name='unit_box_1'>
        <pose>-1.2185 0.799322 0.5 0 -0 0</pose>
        <link name='link'>
          <pose>-1.2185 0.799322 0.5 0 -0 0</pose>
          <velocity>0 0 0 0 -0 0</velocity>
          <acceleration>0 0 0 0 -0 0</acceleration>
          <wrench>0 0 0 0 -0 0</wrench>
        </link>
      </model>
      <model name='unit_box_2'>
        <pose>0.549139 -1 0.5 0 -0 0</pose>
        <link name='link'>
          <pose>0.549139 -1 0.5 0 -0 0</pose>
          <velocity>0 0 0 0 -0 0</velocity>
          <acceleration>-0 -0 0 0 -0 0</acceleration>
          <wrench>-0 -0 0 0 -0 0</wrench>
        </link>
      </model>
      <model name='unit_box_3'>
        <pose>1 1 0.5 0 -0 0</pose>
        <link name='link'>
          <pose>1 1 0.5 0 -0 0</pose>
          <velocity>0 0 0 0 -0 0</velocity>
          <acceleration>-0 0 -0 0 -0 0</acceleration>
          <wrench>-0 0 -0 0 -0 0</wrench>
        </link>
      </model>
    </state>
    <gui fullscreen='0'>
      <camera name='user_camera'>
        <pose>5.48576 -6.86759 12.092 0 0.911643 2.27619</pose>
        <view_controller>orbit</view_controller>
      </camera>
    </gui>
  </world>
</sdf>
