<sdf version='1.5'>
  <world name='default'>
    <light name='sun' type='directional'>
      <cast_shadows>1</cast_shadows>
      <pose>0 0 10 0 -0 0</pose>
      <diffuse>0.8 0.8 0.8 1</diffuse>
      <specular>0.2 0.2 0.2 1</specular>
      <attenuation>
        <range>1000</range>
        <constant>0.9</constant>
        <linear>0.01</linear>
        <quadratic>0.001</quadratic>
      </attenuation>
      <direction>-0.5 0.1 -0.9</direction>
    </light>
    <model name='ground_plane'>
      <static>1</static>
      <link name='link'>
        <collision name='collision'>
          <geometry>
            <plane>
              <normal>0 0 1</normal>
              <size>100 100</size>
            </plane>
          </geometry>
          <surface>
            <friction>
              <ode>
                <mu>100</mu>
                <mu2>50</mu2>
              </ode>
            </friction>
            <contact>
              <ode/>
            </contact>
            <bounce/>
          </surface>
          <max_contacts>10</max_contacts>
        </collision>
        <visual name='visual'>
          <cast_shadows>0</cast_shadows>
          <geometry>
            <plane>
              <normal>0 0 1</normal>
              <size>100 100</size>
            </plane>
          </geometry>
          <material>
            <script>
              <uri>file://media/materials/scripts/gazebo.material</uri>
              <name>Gazebo/Grey</name>
            </script>
          </material>
        </visual>
        <self_collide>0</self_collide>
        <kinematic>0</kinematic>
        <gravity>1</gravity>
      </link>
    </model>
    <physics name='default_physics' default='0' type='ode'>
      <max_step_size>0.001</max_step_size>
      <real_time_factor>1</real_time_factor>
      <real_time_update_rate>1000</real_time_update_rate>
      <gravity>0 0 -9.8</gravity>
      <magnetic_field>5.5645e-06 2.28758e-05 -4.23884e-05</magnetic_field>
    </physics>
    <scene>
      <ambient>0.4 0.4 0.4 1</ambient>
      <background>0.7 0.7 0.7 1</background>
      <shadows>1</shadows>
    </scene>
    <spherical_coordinates>
      <surface_model>EARTH_WGS84</surface_model>
      <latitude_deg>0</latitude_deg>
      <longitude_deg>0</longitude_deg>
      <elevation>0</elevation>
      <heading_deg>0</heading_deg>
    </spherical_coordinates>
    <model name='unit_box_2'>
      <pose>1 -2 0.5 0 -0 0</pose>
      <link name='link'>
        <inertial>
          <mass>1</mass>
          <inertia>
            <ixx>1</ixx>
            <ixy>0</ixy>
            <ixz>0</ixz>
            <iyy>1</iyy>
            <iyz>0</iyz>
            <izz>1</izz>
          </inertia>
        </inertial>
        <collision name='collision'>
          <geometry>
            <box>
              <size>1 1 1</size>
            </box>
          </geometry>
          <max_contacts>10</max_contacts>
          <surface>
            <contact>
              <ode/>
            </contact>
            <bounce/>
            <friction>
              <ode/>
            </friction>
          </surface>
        </collision>
        <visual name='visual'>
          <geometry>
            <box>
              <size>1 1 1</size>
            </box>
          </geometry>
          <material>
            <script>
              <uri>file://media/materials/scripts/gazebo.material</uri>
              <name>Gazebo/Grey</name>
            </script>
          </material>
        </visual>
        <self_collide>0</self_collide>
        <kinematic>0</kinematic>
        <gravity>1</gravity>
      </link>
    </model>
    <model name='unit_box_3'>
      <pose>1 3 0.5 0 -0 0</pose>
      <link name='link'>
        <inertial>
          <mass>1</mass>
          <inertia>
            <ixx>1</ixx>
            <ixy>0</ixy>
            <ixz>0</ixz>
            <iyy>1</iyy>
            <iyz>0</iyz>
            <izz>1</izz>
          </inertia>
        </inertial>
        <collision name='collision'>
          <geometry>
            <box>
              <size>1 1 1</size>
            </box>
          </geometry>
          <max_contacts>10</max_contacts>
          <surface>
            <contact>
              <ode/>
            </contact>
            <bounce/>
            <friction>
              <ode/>
            </friction>
          </surface>
        </collision>
        <visual name='visual'>
          <geometry>
            <box>
              <size>1 1 1</size>
            </box>
          </geometry>
          <material>
            <script>
              <uri>file://media/materials/scripts/gazebo.material</uri>
              <name>Gazebo/Grey</name>
            </script>
          </material>
        </visual>
        <self_collide>0</self_collide>
        <kinematic>0</kinematic>
        <gravity>1</gravity>
      </link>
    </model>
    <model name='unit_box_4'>
      <pose>-0.471036 2 0.5 0 -0 0</pose>
      <link name='link'>
        <inertial>
          <mass>1</mass>
          <inertia>
            <ixx>1</ixx>
            <ixy>0</ixy>
            <ixz>0</ixz>
            <iyy>1</iyy>
            <iyz>0</iyz>
            <izz>1</izz>
          </inertia>
        </inertial>
        <collision name='collision'>
          <geometry>
            <box>
              <size>1.75504 1 1</size>
            </box>
          </geometry>
          <max_contacts>10</max_contacts>
          <surface>
            <contact>
              <ode/>
            </contact>
            <bounce/>
            <friction>
              <ode/>
            </friction>
          </surface>
        </collision>
        <visual name='visual'>
          <geometry>
            <box>
              <size>1.75505 1 1</size>
            </box>
          </geometry>
          <material>
            <script>
              <uri>file://media/materials/scripts/gazebo.material</uri>
              <name>Gazebo/Grey</name>
            </script>
          </material>
        </visual>
        <self_collide>0</self_collide>
        <kinematic>0</kinematic>
        <gravity>1</gravity>
      </link>
    </model>
    <model name='unit_box_5'>
      <pose>1 3 0.5 0 -0 0</pose>
      <link name='link'>
        <inertial>
          <mass>1</mass>
          <inertia>
            <ixx>1</ixx>
            <ixy>0</ixy>
            <ixz>0</ixz>
            <iyy>1</iyy>
            <iyz>0</iyz>
            <izz>1</izz>
          </inertia>
        </inertial>
        <collision name='collision'>
          <geometry>
            <box>
              <size>1.73155 1 1</size>
            </box>
          </geometry>
          <max_contacts>10</max_contacts>
          <surface>
            <contact>
              <ode/>
            </contact>
            <bounce/>
            <friction>
              <ode/>
            </friction>
          </surface>
        </collision>
        <visual name='visual'>
          <geometry>
            <box>
              <size>1.73155 1 1</size>
            </box>
          </geometry>
          <material>
            <script>
              <uri>file://media/materials/scripts/gazebo.material</uri>
              <name>Gazebo/Grey</name>
            </script>
          </material>
        </visual>
        <self_collide>0</self_collide>
        <kinematic>0</kinematic>
        <gravity>1</gravity>
      </link>
    </model>
    <model name='AMiRo Hokuyo tilted_0'>
      <static>0</static>
      <static>0</static>
      <link name='AMiRo::chassis'>
        <inertial>
          <mass>0.4</mass>
          <inertia>
            <ixx>0.0012</ixx>
            <ixy>0</ixy>
            <ixz>0</ixz>
            <iyy>0.0012</iyy>
            <iyz>0</iyz>
            <izz>0.005</izz>
          </inertia>
        </inertial>
        <velocity_decay>
          <linear>0</linear>
          <angular>0</angular>
        </velocity_decay>
        <collision name='collision_DiWheelDrive'>
          <pose>0 0 0.011 0 -0 0</pose>
          <geometry>
            <cylinder>
              <radius>0.05</radius>
              <length>0.002</length>
            </cylinder>
          </geometry>
          <max_contacts>10</max_contacts>
          <surface>
            <contact>
              <ode/>
            </contact>
            <bounce/>
            <friction>
              <ode/>
            </friction>
          </surface>
        </collision>
        <visual name='visual_DiWheelDrive'>
          <pose>0 0 0.011 0 -0 0</pose>
          <geometry>
            <cylinder>
              <radius>0.05</radius>
              <length>0.002</length>
            </cylinder>
          </geometry>
        </visual>
        <collision name='collision_SensorRing'>
          <pose>0 0 0.037 0 -0 0</pose>
          <geometry>
            <cylinder>
              <radius>0.05</radius>
              <length>0.051</length>
            </cylinder>
          </geometry>
          <max_contacts>10</max_contacts>
          <surface>
            <contact>
              <ode/>
            </contact>
            <bounce/>
            <friction>
              <ode/>
            </friction>
          </surface>
        </collision>
        <visual name='visual_SensorRing'>
          <pose>0 0 0.037 0 -0 0</pose>
          <geometry>
            <cylinder>
              <radius>0.05</radius>
              <length>0.051</length>
            </cylinder>
          </geometry>
        </visual>
        <collision name='collision_Hat'>
          <pose>0 0 0.073 0 -0 0</pose>
          <geometry>
            <cylinder>
              <radius>0.05</radius>
              <length>0.02</length>
            </cylinder>
          </geometry>
          <max_contacts>10</max_contacts>
          <surface>
            <contact>
              <ode/>
            </contact>
            <bounce/>
            <friction>
              <ode/>
            </friction>
          </surface>
        </collision>
        <visual name='visual_Hat'>
          <pose>0 0 0.073 0 -0 0</pose>
          <geometry>
            <cylinder>
              <radius>0.05</radius>
              <length>0.02</length>
            </cylinder>
          </geometry>
        </visual>
        <collision name='collision_sph_caster_front'>
          <pose>0.042 0 0.0025 0 -0 0</pose>
          <laser_retro>0</laser_retro>
          <geometry>
            <sphere>
              <radius>0.002</radius>
            </sphere>
          </geometry>
          <surface>
            <friction>
              <ode>
                <mu>0.01</mu>
                <mu2>0.01</mu2>
                <fdir1>0 0 0</fdir1>
                <slip1>0</slip1>
                <slip2>0</slip2>
              </ode>
            </friction>
            <bounce>
              <restitution_coefficient>0</restitution_coefficient>
              <threshold>100000</threshold>
            </bounce>
            <contact>
              <ode>
                <soft_cfm>0</soft_cfm>
                <soft_erp>0.2</soft_erp>
                <kp>1e+12</kp>
                <kd>1</kd>
                <max_vel>100</max_vel>
                <min_depth>0.001</min_depth>
              </ode>
            </contact>
          </surface>
          <max_contacts>10</max_contacts>
        </collision>
        <visual name='visual_sph_caster_front'>
          <pose>0.042 0 0.0025 0 -0 0</pose>
          <geometry>
            <sphere>
              <radius>0.002</radius>
            </sphere>
          </geometry>
        </visual>
        <collision name='collision_cyl_caster_front'>
          <pose>0.042 0 0.0065 0 -0 0</pose>
          <geometry>
            <cylinder>
              <radius>0.003</radius>
              <length>0.007</length>
            </cylinder>
          </geometry>
          <surface>
            <friction>
              <ode>
                <mu>0</mu>
                <mu2>0</mu2>
              </ode>
              <bullet>
                <friction>0</friction>
                <friction2>0</friction2>
              </bullet>
            </friction>
            <contact>
              <collide_without_contact>0</collide_without_contact>
              <ode/>
            </contact>
            <bounce/>
          </surface>
          <max_contacts>10</max_contacts>
        </collision>
        <visual name='visual_cyl_caster_front'>
          <pose>0.042 0 0.0065 0 -0 0</pose>
          <geometry>
            <cylinder>
              <radius>0.003</radius>
              <length>0.007</length>
            </cylinder>
          </geometry>
        </visual>
        <collision name='collision_sph_caster_back'>
          <pose>-0.042 0 0.0025 0 -0 0</pose>
          <geometry>
            <sphere>
              <radius>0.002</radius>
            </sphere>
          </geometry>
          <surface>
            <friction>
              <ode>
                <mu>0.01</mu>
                <mu2>0.01</mu2>
                <fdir1>0 0 0</fdir1>
                <slip1>0</slip1>
                <slip2>0</slip2>
              </ode>
            </friction>
            <bounce>
              <restitution_coefficient>0</restitution_coefficient>
              <threshold>100000</threshold>
            </bounce>
            <contact>
              <ode>
                <soft_cfm>0</soft_cfm>
                <soft_erp>0.2</soft_erp>
                <kp>1e+12</kp>
                <kd>1</kd>
                <max_vel>100</max_vel>
                <min_depth>0.001</min_depth>
              </ode>
            </contact>
          </surface>
          <max_contacts>10</max_contacts>
        </collision>
        <visual name='visual_sph_caster_back'>
          <pose>-0.042 0 0.0025 0 -0 0</pose>
          <geometry>
            <sphere>
              <radius>0.002</radius>
            </sphere>
          </geometry>
        </visual>
        <collision name='collision_cyl_caster_back'>
          <pose>-0.042 0 0.0065 0 -0 0</pose>
          <geometry>
            <cylinder>
              <radius>0.003</radius>
              <length>0.007</length>
            </cylinder>
          </geometry>
          <max_contacts>10</max_contacts>
          <surface>
            <contact>
              <ode/>
            </contact>
            <bounce/>
            <friction>
              <ode/>
            </friction>
          </surface>
        </collision>
        <visual name='visual_cyl_caster_back'>
          <pose>-0.042 0 0.0065 0 -0 0</pose>
          <geometry>
            <cylinder>
              <radius>0.003</radius>
              <length>0.007</length>
            </cylinder>
          </geometry>
        </visual>
        <pose>0 0 0 0 -0 0</pose>
        <self_collide>0</self_collide>
        <kinematic>0</kinematic>
        <gravity>1</gravity>
      </link>
      <link name='AMiRo::left_wheel'>
        <pose>0 0.035 0.03 -5.76279e-13 1.5707 1.5707</pose>
        <inertial>
          <mass>0.02</mass>
          <inertia>
            <ixx>6.8453e-06</ixx>
            <ixy>0</ixy>
            <ixz>0</ixz>
            <iyy>6.8453e-06</iyy>
            <iyz>0</iyz>
            <izz>7.5625e-06</izz>
          </inertia>
        </inertial>
        <collision name='collision'>
          <geometry>
            <cylinder>
              <radius>0.03</radius>
              <length>0.006</length>
            </cylinder>
          </geometry>
          <max_contacts>10</max_contacts>
          <surface>
            <contact>
              <ode/>
            </contact>
            <bounce/>
            <friction>
              <ode/>
            </friction>
          </surface>
        </collision>
        <visual name='visual'>
          <geometry>
            <cylinder>
              <radius>0.03</radius>
              <length>0.006</length>
            </cylinder>
          </geometry>
        </visual>
        <self_collide>0</self_collide>
        <kinematic>0</kinematic>
        <gravity>1</gravity>
      </link>
      <link name='AMiRo::right_wheel'>
        <pose>0 -0.035 0.03 -5.76279e-13 1.5707 1.5707</pose>
        <inertial>
          <mass>0.02</mass>
          <inertia>
            <ixx>6.8453e-06</ixx>
            <ixy>0</ixy>
            <ixz>0</ixz>
            <iyy>6.8453e-06</iyy>
            <iyz>0</iyz>
            <izz>7.5625e-06</izz>
          </inertia>
        </inertial>
        <collision name='collision'>
          <geometry>
            <cylinder>
              <radius>0.03</radius>
              <length>0.006</length>
            </cylinder>
          </geometry>
          <max_contacts>10</max_contacts>
          <surface>
            <contact>
              <ode/>
            </contact>
            <bounce/>
            <friction>
              <ode/>
            </friction>
          </surface>
        </collision>
        <visual name='visual'>
          <geometry>
            <cylinder>
              <radius>0.03</radius>
              <length>0.006</length>
            </cylinder>
          </geometry>
        </visual>
        <self_collide>0</self_collide>
        <kinematic>0</kinematic>
        <gravity>1</gravity>
      </link>
      <joint name='AMiRo::left_wheel_hinge' type='revolute'>
        <pose>0 0 0 0 -0 0</pose>
        <child>AMiRo::left_wheel</child>
        <parent>AMiRo::chassis</parent>
        <axis>
          <xyz>0 1 0</xyz>
          <use_parent_model_frame>1</use_parent_model_frame>
          <limit>
            <lower>-1e+16</lower>
            <upper>1e+16</upper>
          </limit>
          <dynamics>
            <spring_reference>0</spring_reference>
            <spring_stiffness>0</spring_stiffness>
          </dynamics>
        </axis>
      </joint>
      <joint name='AMiRo::right_wheel_hinge' type='revolute'>
        <pose>0 0 0 0 -0 0</pose>
        <child>AMiRo::right_wheel</child>
        <parent>AMiRo::chassis</parent>
        <axis>
          <xyz>0 1 0</xyz>
          <use_parent_model_frame>1</use_parent_model_frame>
          <limit>
            <lower>-1e+16</lower>
            <upper>1e+16</upper>
          </limit>
          <dynamics>
            <spring_reference>0</spring_reference>
            <spring_stiffness>0</spring_stiffness>
          </dynamics>
        </axis>
      </joint>
      <plugin name='model_push' filename='libgazebo_rsb_wheel.so'>
        <differentialKinematicSubscope>diffKin</differentialKinematicSubscope>
        <baseWidth>0.06</baseWidth>
        <wheelRadius>0.03</wheelRadius>
        <rightWheelMaxForceN>2.4</rightWheelMaxForceN>
        <leftWheelMaxForceN>2.4</leftWheelMaxForceN>
      </plugin>
      <link name='AMiRo::gps'>
        <sensor name='positioning' type='AMiRo::gps'>
          <pose>0 0 0 0 -0 0</pose>
          <always_on>1</always_on>
          <update_rate>10</update_rate>
          <visualize>1</visualize>
        </sensor>
        <pose>0 0 0 0 -0 0</pose>
        <self_collide>0</self_collide>
        <inertial>
          <inertia>
            <ixx>1</ixx>
            <ixy>0</ixy>
            <ixz>0</ixz>
            <iyy>1</iyy>
            <iyz>0</iyz>
            <izz>1</izz>
          </inertia>
          <mass>1</mass>
        </inertial>
        <kinematic>0</kinematic>
        <gravity>1</gravity>
      </link>
      <plugin name='positioning' filename='libgazebo_rsb_gps.so'>
        <alwaysOn>true</alwaysOn>
        <updateRate>10.0</updateRate>
        <gpsSubscope>AMiRo::gps</gpsSubscope>
      </plugin>
      <plugin name='odometry' filename='libgazebo_rsb_odom_amiro.so'>
        <alwaysOn>true</alwaysOn>
        <updateRate>10.0</updateRate>
        <odomSubscope>odom</odomSubscope>
        <baseWidth>0.055</baseWidth>
        <kl>0.01</kl>
        <kr>0.01</kr>
      </plugin>
      <link name='hokuyo::link'>
        <inertial>
          <mass>0.1</mass>
          <inertia>
            <ixx>4.56e-05</ixx>
            <ixy>0</ixy>
            <ixz>0</ixz>
            <iyy>4.56e-05</iyy>
            <iyz>0</iyz>
            <izz>3.12e-05</izz>
          </inertia>
        </inertial>
        <visual name='visual'>
          <geometry>
            <mesh>
              <uri>model://hokuyo/meshes/hokuyo.dae</uri>
            </mesh>
          </geometry>
        </visual>
        <collision name='collision-base'>
          <pose>0 0 -0.0145 0 -0 0</pose>
          <geometry>
            <box>
              <size>0.05 0.05 0.041</size>
            </box>
          </geometry>
          <max_contacts>10</max_contacts>
          <surface>
            <contact>
              <ode/>
            </contact>
            <bounce/>
            <friction>
              <ode/>
            </friction>
          </surface>
        </collision>
        <collision name='collision-top'>
          <pose>0 0 0.0205 0 -0 0</pose>
          <geometry>
            <cylinder>
              <radius>0.021</radius>
              <length>0.029</length>
            </cylinder>
          </geometry>
          <max_contacts>10</max_contacts>
          <surface>
            <contact>
              <ode/>
            </contact>
            <bounce/>
            <friction>
              <ode/>
            </friction>
          </surface>
        </collision>
        <sensor name='laser' type='ray'>
          <pose>0.01 0 0.0175 0 -0 0</pose>
          <ray>
            <scan>
              <horizontal>
                <samples>91</samples>
                <resolution>1</resolution>
                <min_angle>-1.5</min_angle>
                <max_angle>1.5</max_angle>
              </horizontal>
            </scan>
            <range>
              <min>0.08</min>
              <max>5</max>
              <resolution>0.01</resolution>
            </range>
          </ray>
          <plugin name='laser' filename='libgazebo_rsb_laser.so'>
            <lidarSubscope>lidar</lidarSubscope>
          </plugin>
          <always_on>1</always_on>
          <update_rate>10</update_rate>
          <visualize>1</visualize>
        </sensor>
        <pose>-0.00697 0 0.125 0 0.5234 0</pose>
        <self_collide>0</self_collide>
        <kinematic>0</kinematic>
        <gravity>1</gravity>
      </link>
      <joint name='hokuyo_joint' type='revolute'>
        <child>hokuyo::link</child>
        <parent>AMiRo::chassis</parent>
        <axis>
          <xyz>0 0 1</xyz>
          <limit>
            <upper>0</upper>
            <lower>0</lower>
          </limit>
          <use_parent_model_frame>1</use_parent_model_frame>
          <dynamics>
            <spring_reference>0</spring_reference>
            <spring_stiffness>0</spring_stiffness>
          </dynamics>
        </axis>
      </joint>
      <pose>1 0.421843 0 0 -0 0</pose>
    </model>
    <model name='unit_box_6'>
      <pose>0.560839 0.539878 0.5 0 -0 0</pose>
      <link name='link'>
        <inertial>
          <mass>1</mass>
          <inertia>
            <ixx>1</ixx>
            <ixy>0</ixy>
            <ixz>0</ixz>
            <iyy>1</iyy>
            <iyz>0</iyz>
            <izz>1</izz>
          </inertia>
        </inertial>
        <collision name='collision'>
          <geometry>
            <box>
              <size>0.097627 0.105557 0.229269</size>
            </box>
          </geometry>
          <max_contacts>10</max_contacts>
          <surface>
            <contact>
              <ode/>
            </contact>
            <bounce/>
            <friction>
              <ode/>
            </friction>
          </surface>
        </collision>
        <visual name='visual'>
          <geometry>
            <box>
              <size>0.097627 0.105557 0.229269</size>
            </box>
          </geometry>
          <material>
            <script>
              <uri>file://media/materials/scripts/gazebo.material</uri>
              <name>Gazebo/Grey</name>
            </script>
          </material>
        </visual>
        <self_collide>0</self_collide>
        <kinematic>0</kinematic>
        <gravity>1</gravity>
      </link>
    </model>
    <state world_name='default'>
      <sim_time>14 570000000</sim_time>
      <real_time>14 639477550</real_time>
      <wall_time>1429814416 548564095</wall_time>
      <model name='AMiRo Hokuyo tilted_0'>
        <pose>0.893735 0.100385 0 4.3e-05 -0.011375 0.00128</pose>
        <link name='AMiRo::chassis'>
          <pose>0.893735 0.100385 0 4.3e-05 -0.011375 0.00128</pose>
          <velocity>0.000146 0.00028 -0.001541 0.037475 -0.035089 0.000335</velocity>
          <acceleration>0.005188 1.09286 -2.51113 0.170544 -0.004976 -0.003535</acceleration>
          <wrench>0.002075 0.437144 -1.00445 0 -0 0</wrench>
        </link>
        <link name='AMiRo::gps'>
          <pose>0.893808 0.100017 -16.3648 0 -0 0</pose>
          <velocity>0 0 -17.9046 0 -0 0</velocity>
          <acceleration>0 0 -9.8 0 -0 0</acceleration>
          <wrench>0 0 -9.8 0 -0 0</wrench>
        </link>
        <link name='AMiRo::left_wheel'>
          <pose>0.893349 0.135382 0.03 -1.56965 1.56066 0.002335</pose>
          <velocity>-0.000926 -0.000943 -2e-05 0.032079 -0.030993 0.000555</velocity>
          <acceleration>-0.038758 -0.94004 0.053797 0.010901 -0.000435 -0.000106</acceleration>
          <wrench>-0.000775 -0.018801 0.001076 0 -0 0</wrench>
        </link>
        <link name='AMiRo::right_wheel'>
          <pose>0.893439 0.065384 0.029997 -1.55191 1.56102 0.020073</pose>
          <velocity>-0.000857 -0.000975 -0.003029 0.026294 -0.035105 0.00066</velocity>
          <acceleration>0.007808 -0.966283 -4.92307 0.009098 -0.00213 9.6e-05</acceleration>
          <wrench>0.000156 -0.019326 -0.098461 0 -0 0</wrench>
        </link>
        <link name='hokuyo::link'>
          <pose>0.885344 0.100369 0.124913 5e-05 0.512025 0.001305</pose>
          <velocity>-0.004237 -0.004369 -0.001839 0.037172 -0.03509 0.000169</velocity>
          <acceleration>-0.2023 -5.91985 -2.53446 0.025585 -0.000758 -0.000122</acceleration>
          <wrench>-0.02023 -0.591985 -0.253446 0 -0 0</wrench>
        </link>
      </model>
      <model name='ground_plane'>
        <pose>0 0 0 0 -0 0</pose>
        <link name='link'>
          <pose>0 0 0 0 -0 0</pose>
          <velocity>0 0 0 0 -0 0</velocity>
          <acceleration>0 0 0 0 -0 0</acceleration>
          <wrench>0 0 0 0 -0 0</wrench>
        </link>
      </model>
      <model name='unit_box_2'>
        <pose>-0.5 0.4 0.5 0 -0 0</pose>
        <link name='link'>
          <pose>-0.5 0.4 0.5 0 -0 0</pose>
          <velocity>0 0 0 0 -0 0</velocity>
          <acceleration>-0 -0 0 0 -0 0</acceleration>
          <wrench>-0 -0 0 0 -0 0</wrench>
        </link>
      </model>
      <model name='unit_box_3'>
        <pose>2.3 0.35 0.5 0 -0 0</pose>
        <link name='link'>
          <pose>2.3 0.35 0.5 0 -0 0</pose>
          <velocity>0 0 0 0 -0 0</velocity>
          <acceleration>-0 -0 0 0 -0 0</acceleration>
          <wrench>-0 -0 0 0 -0 0</wrench>
        </link>
      </model>
      <model name='unit_box_4'>
        <pose>0.9 -0.5 0.5 0 -0 0</pose>
        <link name='link'>
          <pose>0.9 -0.5 0.5 0 -0 0</pose>
          <velocity>0 0 0 0 -0 0</velocity>
          <acceleration>0 0 0 0 -0 0</acceleration>
          <wrench>0 0 0 0 -0 0</wrench>
        </link>
      </model>
      <model name='unit_box_5'>
        <pose>0.9 1.3 0.5 0 -0 0</pose>
        <link name='link'>
          <pose>0.9 1.3 0.5 0 -0 0</pose>
          <velocity>0 0 0 0 -0 0</velocity>
          <acceleration>0 -0 0 0 -0 0</acceleration>
          <wrench>0 -0 0 0 -0 0</wrench>
        </link>
      </model>
      <model name='unit_box_6'>
        <pose>0.889313 0.398818 0.115001 -1e-06 0.005589 -0.000109</pose>
        <link name='link'>
          <pose>0.889313 0.398818 0.115001 -1e-06 0.005589 -0.000109</pose>
          <velocity>0.000207 2.9e-05 0.000131 -0.000247 0.001803 -4e-06</velocity>
          <acceleration>-0.072187 -0.058291 -0.06794 0.50687 -0.627711 0</acceleration>
          <wrench>-0.072187 -0.058291 -0.06794 0 -0 0</wrench>
        </link>
      </model>
    </state>
    <gui fullscreen='0'>
      <camera name='user_camera'>
        <pose>1.23998 0.405686 0.959696 -2.80583e-16 1.37164 2.43219</pose>
        <view_controller>orbit</view_controller>
      </camera>
    </gui>
  </world>
</sdf>
