<sdf version='1.5'>
  <world name='default'>
    <light name='sun' type='directional'>
      <cast_shadows>1</cast_shadows>
      <pose>0 0 10 0 -0 0</pose>
      <diffuse>0.8 0.8 0.8 1</diffuse>
      <specular>0.2 0.2 0.2 1</specular>
      <attenuation>
        <range>1000</range>
        <constant>0.9</constant>
        <linear>0.01</linear>
        <quadratic>0.001</quadratic>
      </attenuation>
      <direction>-0.5 0.1 -0.9</direction>
    </light>
    <model name='ground_plane'>
      <static>1</static>
      <link name='link'>
        <collision name='collision'>
          <geometry>
            <plane>
              <normal>0 0 1</normal>
              <size>100 100</size>
            </plane>
          </geometry>
          <surface>
            <friction>
              <ode>
                <mu>100</mu>
                <mu2>50</mu2>
              </ode>
            </friction>
            <contact>
              <ode/>
            </contact>
            <bounce/>
          </surface>
          <max_contacts>10</max_contacts>
        </collision>
        <visual name='visual'>
          <cast_shadows>0</cast_shadows>
          <geometry>
            <plane>
              <normal>0 0 1</normal>
              <size>100 100</size>
            </plane>
          </geometry>
          <material>
            <script>
              <uri>file://media/materials/scripts/gazebo.material</uri>
              <name>Gazebo/Grey</name>
            </script>
          </material>
        </visual>
        <self_collide>0</self_collide>
        <kinematic>0</kinematic>
        <gravity>1</gravity>
      </link>
    </model>
    <physics name='default_physics' default='0' type='ode'>
      <max_step_size>0.001</max_step_size>
      <real_time_factor>1</real_time_factor>
      <real_time_update_rate>1000</real_time_update_rate>
      <gravity>0 0 -9.8</gravity>
      <magnetic_field>5.5645e-06 2.28758e-05 -4.23884e-05</magnetic_field>
    </physics>
    <scene>
      <ambient>0.4 0.4 0.4 1</ambient>
      <background>0.7 0.7 0.7 1</background>
      <shadows>1</shadows>
    </scene>
    <spherical_coordinates>
      <surface_model>EARTH_WGS84</surface_model>
      <latitude_deg>0</latitude_deg>
      <longitude_deg>0</longitude_deg>
      <elevation>0</elevation>
      <heading_deg>0</heading_deg>
    </spherical_coordinates>
    <model name='unit_box_6'>
      <pose>0.560839 0.539878 0.5 0 -0 0</pose>
      <link name='link'>
        <inertial>
          <mass>1</mass>
          <inertia>
            <ixx>1</ixx>
            <ixy>0</ixy>
            <ixz>0</ixz>
            <iyy>1</iyy>
            <iyz>0</iyz>
            <izz>1</izz>
          </inertia>
        </inertial>
        <collision name='collision'>
          <geometry>
            <box>
              <size>0.1 0.06 0.2</size>
            </box>
          </geometry>
          <max_contacts>10</max_contacts>
          <surface>
            <contact>
              <ode/>
            </contact>
            <bounce/>
            <friction>
              <ode/>
            </friction>
          </surface>
        </collision>
        <visual name='visual'>
          <geometry>
            <box>
              <size>0.1 0.06 0.2</size>
            </box>
          </geometry>
          <material>
            <script>
              <uri>file://media/materials/scripts/gazebo.material</uri>
              <name>Gazebo/Grey</name>
            </script>
          </material>
        </visual>
        <self_collide>0</self_collide>
        <kinematic>0</kinematic>
        <gravity>1</gravity>
      </link>
    </model>
    <state world_name='default'>
      <sim_time>26 564000000</sim_time>
      <real_time>4 488369770</real_time>
      <wall_time>1429924212 98615228</wall_time>
      <model name='AMiRo Hokuyo'>
        <pose>0.877106 0.105616 0 -1.5e-05 -0.002033 -2.57291</pose>
        <link name='AMiRo::chassis'>
          <pose>0.877106 0.105616 0 -1.5e-05 -0.002033 -2.57291</pose>
          <velocity>-0.000967 -0.000765 0.004775 0.001422 -0.002564 -1.27591</velocity>
          <acceleration>-0.008258 -0.01359 9.54849 -0.001003 -0.000442 -0.002869</acceleration>
          <wrench>-0.003303 -0.005436 3.8194 0 -0 0</wrench>
        </link>
        <link name='AMiRo::gps'>
          <pose>0.877348 0.105965 -84.9402 0 -0 0</pose>
          <velocity>0 0 -40.7974 0 -0 0</velocity>
          <acceleration>0 0 -9.8 0 -0 0</acceleration>
          <wrench>0 0 -9.8 0 -0 0</wrench>
        </link>
        <link name='AMiRo::left_wheel'>
          <pose>0.896006 0.076158 0.030001 -1.57229 -1.48819 -2.57109</pose>
          <velocity>-0.038643 -0.024836 0.004932 0.815666 -1.2683 -1.23153</velocity>
          <acceleration>-0.108545 0.26211 9.86505 0.002041 -0.000712 0.033503</acceleration>
          <wrench>-0.002171 0.005242 0.197301 0 -0 0</wrench>
        </link>
        <link name='AMiRo::right_wheel'>
          <pose>0.85831 0.135141 0.030001 1.57225 -1.48188 0.567551</pose>
          <velocity>0.036678 0.023402 0.004728 -0.792275 1.2424 -1.23124</velocity>
          <acceleration>0.156563 0.359948 9.4557 0.006532 -0.005371 0.033656</acceleration>
          <wrench>0.003131 0.007199 0.189114 0 -0 0</wrench>
        </link>
        <link name='hokuyo::link'>
          <pose>0.877309 0.105744 0.118 -1.6e-05 -0.002033 -2.57291</pose>
          <velocity>-0.001094 -0.001218 0.00477 0.001619 -0.00244 -1.27611</velocity>
          <acceleration>-0.003337 -0.026206 9.53692 2.6e-05 3.9e-05 -0.000206</acceleration>
          <wrench>-0.000334 -0.002621 0.953692 0 -0 0</wrench>
        </link>
      </model>
      <model name='ground_plane'>
        <pose>0 0 0 0 -0 0</pose>
        <link name='link'>
          <pose>0 0 0 0 -0 0</pose>
          <velocity>0 0 0 0 -0 0</velocity>
          <acceleration>0 0 0 0 -0 0</acceleration>
          <wrench>0 0 0 0 -0 0</wrench>
        </link>
      </model>
      <model name='unit_box_6'>
        <pose>0.774803 0.536784 0.10009 0.003003 1e-06 1.11112</pose>
        <link name='link'>
          <pose>0.774803 0.536784 0.10009 0.003003 1e-06 1.11112</pose>
          <velocity>0 0 0 0 -0 0</velocity>
          <acceleration>-0.047824 -0.031152 0.116609 0.310586 -0.479121 -7e-06</acceleration>
          <wrench>-0.047824 -0.031152 0.116609 0 -0 0</wrench>
        </link>
      </model>
      <model name='unit_box_6_clone'>
        <pose>1.34057 0.486998 0.100069 0.001227 0.000642 -0.804335</pose>
        <link name='link'>
          <pose>1.34057 0.486998 0.100069 0.001227 0.000642 -0.804335</pose>
          <velocity>0 0 0 0 -0 0</velocity>
          <acceleration>0 0 -9.83806 -2.97721 -1.0264 1.49709</acceleration>
          <wrench>0 0 -9.83806 0 -0 0</wrench>
        </link>
      </model>
      <model name='unit_box_6_clone_0'>
        <pose>0.289412 0.282527 0.100077 0.000617 -0.001366 -0.544569</pose>
        <link name='link'>
          <pose>0.289412 0.282527 0.100077 0.000617 -0.001366 -0.544569</pose>
          <velocity>0 0 0 0 -0 0</velocity>
          <acceleration>0 0 -9.8 0 0.000175 0</acceleration>
          <wrench>0 0 -9.8 0 -0 0</wrench>
        </link>
      </model>
    </state>
    <gui fullscreen='0'>
      <camera name='user_camera'>
        <pose>1.16369 0.114517 2.36345 -2.80583e-16 1.37164 2.43219</pose>
        <view_controller>orbit</view_controller>
      </camera>
    </gui>
    <model name='unit_box_6_clone'>
      <pose>1.41853 0.44792 0.100254 3e-06 -0.005113 -0.000127</pose>
      <link name='link'>
        <inertial>
          <mass>1</mass>
          <inertia>
            <ixx>1</ixx>
            <ixy>0</ixy>
            <ixz>0</ixz>
            <iyy>1</iyy>
            <iyz>0</iyz>
            <izz>1</izz>
          </inertia>
        </inertial>
        <collision name='collision'>
          <geometry>
            <box>
              <size>0.1 0.06 0.2</size>
            </box>
          </geometry>
          <max_contacts>10</max_contacts>
          <surface>
            <contact>
              <ode/>
            </contact>
            <bounce/>
            <friction>
              <ode/>
            </friction>
          </surface>
        </collision>
        <visual name='visual'>
          <geometry>
            <box>
              <size>0.1 0.06 0.2</size>
            </box>
          </geometry>
          <material>
            <script>
              <uri>file://media/materials/scripts/gazebo.material</uri>
              <name>Gazebo/Grey</name>
            </script>
          </material>
        </visual>
        <self_collide>0</self_collide>
        <kinematic>0</kinematic>
        <gravity>1</gravity>
      </link>
    </model>
    <model name='unit_box_6_clone_0'>
      <pose>0.409785 0.429859 0.100254 3e-06 -0.005113 -0.000127</pose>
      <link name='link'>
        <inertial>
          <mass>1</mass>
          <inertia>
            <ixx>1</ixx>
            <ixy>0</ixy>
            <ixz>0</ixz>
            <iyy>1</iyy>
            <iyz>0</iyz>
            <izz>1</izz>
          </inertia>
        </inertial>
        <collision name='collision'>
          <geometry>
            <box>
              <size>0.1 0.06 0.2</size>
            </box>
          </geometry>
          <max_contacts>10</max_contacts>
          <surface>
            <contact>
              <ode/>
            </contact>
            <bounce/>
            <friction>
              <ode/>
            </friction>
          </surface>
        </collision>
        <visual name='visual'>
          <geometry>
            <box>
              <size>0.1 0.06 0.2</size>
            </box>
          </geometry>
          <material>
            <script>
              <uri>file://media/materials/scripts/gazebo.material</uri>
              <name>Gazebo/Grey</name>
            </script>
          </material>
        </visual>
        <self_collide>0</self_collide>
        <kinematic>0</kinematic>
        <gravity>1</gravity>
      </link>
    </model>
    <model name='AMiRo Hokuyo'>
      <static>0</static>
      <static>0</static>
      <link name='AMiRo::chassis'>
        <inertial>
          <mass>0.4</mass>
          <inertia>
            <ixx>0.0012</ixx>
            <ixy>0</ixy>
            <ixz>0</ixz>
            <iyy>0.0012</iyy>
            <iyz>0</iyz>
            <izz>0.005</izz>
          </inertia>
        </inertial>
        <velocity_decay>
          <linear>0</linear>
          <angular>0</angular>
        </velocity_decay>
        <collision name='collision_DiWheelDrive'>
          <pose>0 0 0.011 0 -0 0</pose>
          <geometry>
            <cylinder>
              <radius>0.05</radius>
              <length>0.002</length>
            </cylinder>
          </geometry>
          <max_contacts>10</max_contacts>
          <surface>
            <contact>
              <ode/>
            </contact>
            <bounce/>
            <friction>
              <ode/>
            </friction>
          </surface>
        </collision>
        <visual name='visual_DiWheelDrive'>
          <pose>0 0 0.011 0 -0 0</pose>
          <geometry>
            <cylinder>
              <radius>0.05</radius>
              <length>0.002</length>
            </cylinder>
          </geometry>
        </visual>
        <collision name='collision_SensorRing'>
          <pose>0 0 0.037 0 -0 0</pose>
          <geometry>
            <cylinder>
              <radius>0.05</radius>
              <length>0.051</length>
            </cylinder>
          </geometry>
          <max_contacts>10</max_contacts>
          <surface>
            <contact>
              <ode/>
            </contact>
            <bounce/>
            <friction>
              <ode/>
            </friction>
          </surface>
        </collision>
        <visual name='visual_SensorRing'>
          <pose>0 0 0.037 0 -0 0</pose>
          <geometry>
            <cylinder>
              <radius>0.05</radius>
              <length>0.051</length>
            </cylinder>
          </geometry>
        </visual>
        <collision name='collision_Hat'>
          <pose>0 0 0.073 0 -0 0</pose>
          <geometry>
            <cylinder>
              <radius>0.05</radius>
              <length>0.02</length>
            </cylinder>
          </geometry>
          <max_contacts>10</max_contacts>
          <surface>
            <contact>
              <ode/>
            </contact>
            <bounce/>
            <friction>
              <ode/>
            </friction>
          </surface>
        </collision>
        <visual name='visual_Hat'>
          <pose>0 0 0.073 0 -0 0</pose>
          <geometry>
            <cylinder>
              <radius>0.05</radius>
              <length>0.02</length>
            </cylinder>
          </geometry>
        </visual>
        <collision name='collision_sph_caster_front'>
          <pose>0.042 0 0.0025 0 -0 0</pose>
          <laser_retro>0</laser_retro>
          <geometry>
            <sphere>
              <radius>0.002</radius>
            </sphere>
          </geometry>
          <surface>
            <friction>
              <ode>
                <mu>0.01</mu>
                <mu2>0.01</mu2>
                <fdir1>0 0 0</fdir1>
                <slip1>0</slip1>
                <slip2>0</slip2>
              </ode>
            </friction>
            <bounce>
              <restitution_coefficient>0</restitution_coefficient>
              <threshold>100000</threshold>
            </bounce>
            <contact>
              <ode>
                <soft_cfm>0</soft_cfm>
                <soft_erp>0.2</soft_erp>
                <kp>1e+12</kp>
                <kd>1</kd>
                <max_vel>100</max_vel>
                <min_depth>0.001</min_depth>
              </ode>
            </contact>
          </surface>
          <max_contacts>10</max_contacts>
        </collision>
        <visual name='visual_sph_caster_front'>
          <pose>0.042 0 0.0025 0 -0 0</pose>
          <geometry>
            <sphere>
              <radius>0.002</radius>
            </sphere>
          </geometry>
        </visual>
        <collision name='collision_cyl_caster_front'>
          <pose>0.042 0 0.0065 0 -0 0</pose>
          <geometry>
            <cylinder>
              <radius>0.003</radius>
              <length>0.007</length>
            </cylinder>
          </geometry>
          <surface>
            <friction>
              <ode>
                <mu>0</mu>
                <mu2>0</mu2>
              </ode>
              <bullet>
                <friction>0</friction>
                <friction2>0</friction2>
              </bullet>
            </friction>
            <contact>
              <collide_without_contact>0</collide_without_contact>
              <ode/>
            </contact>
            <bounce/>
          </surface>
          <max_contacts>10</max_contacts>
        </collision>
        <visual name='visual_cyl_caster_front'>
          <pose>0.042 0 0.0065 0 -0 0</pose>
          <geometry>
            <cylinder>
              <radius>0.003</radius>
              <length>0.007</length>
            </cylinder>
          </geometry>
        </visual>
        <collision name='collision_sph_caster_back'>
          <pose>-0.042 0 0.0025 0 -0 0</pose>
          <geometry>
            <sphere>
              <radius>0.002</radius>
            </sphere>
          </geometry>
          <surface>
            <friction>
              <ode>
                <mu>0.01</mu>
                <mu2>0.01</mu2>
                <fdir1>0 0 0</fdir1>
                <slip1>0</slip1>
                <slip2>0</slip2>
              </ode>
            </friction>
            <bounce>
              <restitution_coefficient>0</restitution_coefficient>
              <threshold>100000</threshold>
            </bounce>
            <contact>
              <ode>
                <soft_cfm>0</soft_cfm>
                <soft_erp>0.2</soft_erp>
                <kp>1e+12</kp>
                <kd>1</kd>
                <max_vel>100</max_vel>
                <min_depth>0.001</min_depth>
              </ode>
            </contact>
          </surface>
          <max_contacts>10</max_contacts>
        </collision>
        <visual name='visual_sph_caster_back'>
          <pose>-0.042 0 0.0025 0 -0 0</pose>
          <geometry>
            <sphere>
              <radius>0.002</radius>
            </sphere>
          </geometry>
        </visual>
        <collision name='collision_cyl_caster_back'>
          <pose>-0.042 0 0.0065 0 -0 0</pose>
          <geometry>
            <cylinder>
              <radius>0.003</radius>
              <length>0.007</length>
            </cylinder>
          </geometry>
          <max_contacts>10</max_contacts>
          <surface>
            <contact>
              <ode/>
            </contact>
            <bounce/>
            <friction>
              <ode/>
            </friction>
          </surface>
        </collision>
        <visual name='visual_cyl_caster_back'>
          <pose>-0.042 0 0.0065 0 -0 0</pose>
          <geometry>
            <cylinder>
              <radius>0.003</radius>
              <length>0.007</length>
            </cylinder>
          </geometry>
        </visual>
        <pose>0 0 0 0 -0 0</pose>
        <self_collide>0</self_collide>
        <kinematic>0</kinematic>
        <gravity>1</gravity>
      </link>
      <link name='AMiRo::left_wheel'>
        <pose>0 0.035 0.03 -5.76279e-13 1.5707 1.5707</pose>
        <inertial>
          <mass>0.02</mass>
          <inertia>
            <ixx>6.8453e-06</ixx>
            <ixy>0</ixy>
            <ixz>0</ixz>
            <iyy>6.8453e-06</iyy>
            <iyz>0</iyz>
            <izz>7.5625e-06</izz>
          </inertia>
        </inertial>
        <collision name='collision'>
          <geometry>
            <cylinder>
              <radius>0.03</radius>
              <length>0.006</length>
            </cylinder>
          </geometry>
          <max_contacts>10</max_contacts>
          <surface>
            <contact>
              <ode/>
            </contact>
            <bounce/>
            <friction>
              <ode/>
            </friction>
          </surface>
        </collision>
        <visual name='visual'>
          <geometry>
            <cylinder>
              <radius>0.03</radius>
              <length>0.006</length>
            </cylinder>
          </geometry>
        </visual>
        <self_collide>0</self_collide>
        <kinematic>0</kinematic>
        <gravity>1</gravity>
      </link>
      <link name='AMiRo::right_wheel'>
        <pose>0 -0.035 0.03 -5.76279e-13 1.5707 1.5707</pose>
        <inertial>
          <mass>0.02</mass>
          <inertia>
            <ixx>6.8453e-06</ixx>
            <ixy>0</ixy>
            <ixz>0</ixz>
            <iyy>6.8453e-06</iyy>
            <iyz>0</iyz>
            <izz>7.5625e-06</izz>
          </inertia>
        </inertial>
        <collision name='collision'>
          <geometry>
            <cylinder>
              <radius>0.03</radius>
              <length>0.006</length>
            </cylinder>
          </geometry>
          <max_contacts>10</max_contacts>
          <surface>
            <contact>
              <ode/>
            </contact>
            <bounce/>
            <friction>
              <ode/>
            </friction>
          </surface>
        </collision>
        <visual name='visual'>
          <geometry>
            <cylinder>
              <radius>0.03</radius>
              <length>0.006</length>
            </cylinder>
          </geometry>
        </visual>
        <self_collide>0</self_collide>
        <kinematic>0</kinematic>
        <gravity>1</gravity>
      </link>
      <joint name='AMiRo::left_wheel_hinge' type='revolute'>
        <pose>0 0 0 0 -0 0</pose>
        <child>AMiRo::left_wheel</child>
        <parent>AMiRo::chassis</parent>
        <axis>
          <xyz>0 1 0</xyz>
          <use_parent_model_frame>1</use_parent_model_frame>
          <limit>
            <lower>-1e+16</lower>
            <upper>1e+16</upper>
          </limit>
          <dynamics>
            <spring_reference>0</spring_reference>
            <spring_stiffness>0</spring_stiffness>
          </dynamics>
        </axis>
      </joint>
      <joint name='AMiRo::right_wheel_hinge' type='revolute'>
        <pose>0 0 0 0 -0 0</pose>
        <child>AMiRo::right_wheel</child>
        <parent>AMiRo::chassis</parent>
        <axis>
          <xyz>0 1 0</xyz>
          <use_parent_model_frame>1</use_parent_model_frame>
          <limit>
            <lower>-1e+16</lower>
            <upper>1e+16</upper>
          </limit>
          <dynamics>
            <spring_reference>0</spring_reference>
            <spring_stiffness>0</spring_stiffness>
          </dynamics>
        </axis>
      </joint>
      <plugin name='model_push' filename='libgazebo_rsb_wheel.so'>
        <differentialKinematicSubscope>diffKin</differentialKinematicSubscope>
        <baseWidth>0.06</baseWidth>
        <wheelRadius>0.03</wheelRadius>
        <rightWheelMaxForceN>2.4</rightWheelMaxForceN>
        <leftWheelMaxForceN>2.4</leftWheelMaxForceN>
      </plugin>
      <link name='AMiRo::gps'>
        <sensor name='positioning' type='AMiRo::gps'>
          <pose>0 0 0 0 -0 0</pose>
          <always_on>1</always_on>
          <update_rate>10</update_rate>
          <visualize>1</visualize>
        </sensor>
        <pose>0 0 0 0 -0 0</pose>
        <self_collide>0</self_collide>
        <inertial>
          <inertia>
            <ixx>1</ixx>
            <ixy>0</ixy>
            <ixz>0</ixz>
            <iyy>1</iyy>
            <iyz>0</iyz>
            <izz>1</izz>
          </inertia>
          <mass>1</mass>
        </inertial>
        <kinematic>0</kinematic>
        <gravity>1</gravity>
      </link>
      <plugin name='positioning' filename='libgazebo_rsb_gps.so'>
        <alwaysOn>true</alwaysOn>
        <updateRate>10.0</updateRate>
        <gpsSubscope>AMiRo::gps</gpsSubscope>
      </plugin>
      <plugin name='odometry' filename='libgazebo_rsb_odom_amiro.so'>
        <alwaysOn>true</alwaysOn>
        <updateRate>10.0</updateRate>
        <odomSubscope>odom</odomSubscope>
        <baseWidth>0.055</baseWidth>
        <kl>0.01</kl>
        <kr>0.01</kr>
      </plugin>
      <link name='hokuyo::link'>
        <inertial>
          <mass>0.1</mass>
          <inertia>
            <ixx>4.56e-05</ixx>
            <ixy>0</ixy>
            <ixz>0</ixz>
            <iyy>4.56e-05</iyy>
            <iyz>0</iyz>
            <izz>3.12e-05</izz>
          </inertia>
        </inertial>
        <visual name='visual'>
          <geometry>
            <mesh>
              <uri>model://hokuyo/meshes/hokuyo.dae</uri>
            </mesh>
          </geometry>
        </visual>
        <collision name='collision-base'>
          <pose>0 0 -0.0145 0 -0 0</pose>
          <geometry>
            <box>
              <size>0.05 0.05 0.041</size>
            </box>
          </geometry>
          <max_contacts>10</max_contacts>
          <surface>
            <contact>
              <ode/>
            </contact>
            <bounce/>
            <friction>
              <ode/>
            </friction>
          </surface>
        </collision>
        <collision name='collision-top'>
          <pose>0 0 0.0205 0 -0 0</pose>
          <geometry>
            <cylinder>
              <radius>0.021</radius>
              <length>0.029</length>
            </cylinder>
          </geometry>
          <max_contacts>10</max_contacts>
          <surface>
            <contact>
              <ode/>
            </contact>
            <bounce/>
            <friction>
              <ode/>
            </friction>
          </surface>
        </collision>
        <sensor name='laser' type='ray'>
          <pose>0.01 0 0.0175 0 -0 0</pose>
          <ray>
            <scan>
              <horizontal>
                <samples>91</samples>
                <resolution>1</resolution>
                <min_angle>-1.5</min_angle>
                <max_angle>1.5</max_angle>
              </horizontal>
            </scan>
            <range>
              <min>0.08</min>
              <max>5</max>
              <resolution>0.01</resolution>
            </range>
          </ray>
          <plugin name='laser' filename='libgazebo_rsb_laser.so'>
            <lidarSubscope>lidar</lidarSubscope>
          </plugin>
          <always_on>1</always_on>
          <update_rate>10</update_rate>
          <visualize>1</visualize>
        </sensor>
        <pose>0 0 0.118 0 -0 0</pose>
        <self_collide>0</self_collide>
        <kinematic>0</kinematic>
        <gravity>1</gravity>
      </link>
      <joint name='hokuyo_joint' type='revolute'>
        <child>hokuyo::link</child>
        <parent>AMiRo::chassis</parent>
        <axis>
          <xyz>0 0 1</xyz>
          <limit>
            <upper>0</upper>
            <lower>0</lower>
          </limit>
          <use_parent_model_frame>1</use_parent_model_frame>
          <dynamics>
            <spring_reference>0</spring_reference>
            <spring_stiffness>0</spring_stiffness>
          </dynamics>
        </axis>
      </joint>
      <pose>1 0 0 0 -0 0</pose>
    </model>
  </world>
</sdf>
