<sdf version='1.5'>
  <world name='default'>
    <light name='sun' type='directional'>
      <cast_shadows>1</cast_shadows>
      <pose>0 0 10 0 -0 0</pose>
      <diffuse>0.8 0.8 0.8 1</diffuse>
      <specular>0.2 0.2 0.2 1</specular>
      <attenuation>
        <range>1000</range>
        <constant>0.9</constant>
        <linear>0.01</linear>
        <quadratic>0.001</quadratic>
      </attenuation>
      <direction>-0.5 0.1 -0.9</direction>
    </light>
    <model name='ground_plane'>
      <static>1</static>
      <link name='link'>
        <collision name='collision'>
          <geometry>
            <plane>
              <normal>0 0 1</normal>
              <size>100 100</size>
            </plane>
          </geometry>
          <surface>
            <friction>
              <ode>
                <mu>100</mu>
                <mu2>50</mu2>
              </ode>
            </friction>
            <contact>
              <ode/>
            </contact>
            <bounce/>
          </surface>
          <max_contacts>10</max_contacts>
        </collision>
        <visual name='visual'>
          <cast_shadows>0</cast_shadows>
          <geometry>
            <plane>
              <normal>0 0 1</normal>
              <size>100 100</size>
            </plane>
          </geometry>
          <material>
            <script>
              <uri>file://media/materials/scripts/gazebo.material</uri>
              <name>Gazebo/Grey</name>
            </script>
          </material>
        </visual>
        <velocity_decay>
          <linear>0</linear>
          <angular>0</angular>
        </velocity_decay>
        <self_collide>0</self_collide>
        <kinematic>0</kinematic>
        <gravity>1</gravity>
      </link>
    </model>
    <physics type='ode'>
      <max_step_size>0.001</max_step_size>
      <real_time_factor>1</real_time_factor>
      <real_time_update_rate>100</real_time_update_rate>
      <gravity>0 0 -9.8</gravity>
      <magnetic_field>5.5645e-06 2.28758e-05 -4.23884e-05</magnetic_field>
    </physics>
    <scene>
      <ambient>0.4 0.4 0.4 1</ambient>
      <background>0.7 0.7 0.7 1</background>
      <shadows>1</shadows>
    </scene>
    <spherical_coordinates>
      <surface_model>EARTH_WGS84</surface_model>
      <latitude_deg>0</latitude_deg>
      <longitude_deg>0</longitude_deg>
      <elevation>0</elevation>
      <heading_deg>0</heading_deg>
    </spherical_coordinates>
    <model name='AMiRo Hokuyo Pitch_9'>
      <static>0</static>
      <static>0</static>
      <link name='AMiRo::chassis'>
        <inertial>
          <mass>0.4</mass>
          <inertia>
            <ixx>0.0012</ixx>
            <ixy>0</ixy>
            <ixz>0</ixz>
            <iyy>0.0012</iyy>
            <iyz>0</iyz>
            <izz>0.005</izz>
          </inertia>
        </inertial>
        <velocity_decay>
          <linear>0</linear>
          <angular>0</angular>
        </velocity_decay>
        <collision name='collision_DiWheelDrive'>
          <pose>0 0 0.011 0 -0 0</pose>
          <geometry>
            <cylinder>
              <radius>0.05</radius>
              <length>0.002</length>
            </cylinder>
          </geometry>
          <max_contacts>10</max_contacts>
          <surface>
            <contact>
              <ode/>
            </contact>
            <bounce/>
            <friction>
              <ode/>
            </friction>
          </surface>
        </collision>
        <visual name='visual_DiWheelDrive'>
          <pose>0 0 0.011 0 -0 0</pose>
          <geometry>
            <cylinder>
              <radius>0.05</radius>
              <length>0.002</length>
            </cylinder>
          </geometry>
        </visual>
        <collision name='collision_SensorRing'>
          <pose>0 0 0.037 0 -0 0</pose>
          <geometry>
            <cylinder>
              <radius>0.05</radius>
              <length>0.051</length>
            </cylinder>
          </geometry>
          <max_contacts>10</max_contacts>
          <surface>
            <contact>
              <ode/>
            </contact>
            <bounce/>
            <friction>
              <ode/>
            </friction>
          </surface>
        </collision>
        <visual name='visual_SensorRing'>
          <pose>0 0 0.037 0 -0 0</pose>
          <geometry>
            <cylinder>
              <radius>0.05</radius>
              <length>0.051</length>
            </cylinder>
          </geometry>
        </visual>
        <collision name='collision_Hat'>
          <pose>0 0 0.073 0 -0 0</pose>
          <geometry>
            <cylinder>
              <radius>0.05</radius>
              <length>0.02</length>
            </cylinder>
          </geometry>
          <max_contacts>10</max_contacts>
          <surface>
            <contact>
              <ode/>
            </contact>
            <bounce/>
            <friction>
              <ode/>
            </friction>
          </surface>
        </collision>
        <visual name='visual_Hat'>
          <pose>0 0 0.073 0 -0 0</pose>
          <geometry>
            <cylinder>
              <radius>0.05</radius>
              <length>0.02</length>
            </cylinder>
          </geometry>
        </visual>
        <collision name='collision_sph_caster_front'>
          <pose>0.042 0 0.0025 0 -0 0</pose>
          <laser_retro>0</laser_retro>
          <geometry>
            <sphere>
              <radius>0.002</radius>
            </sphere>
          </geometry>
          <surface>
            <friction>
              <ode>
                <mu>0.01</mu>
                <mu2>0.01</mu2>
                <fdir1>0 0 0</fdir1>
                <slip1>0</slip1>
                <slip2>0</slip2>
              </ode>
            </friction>
            <bounce>
              <restitution_coefficient>0</restitution_coefficient>
              <threshold>100000</threshold>
            </bounce>
            <contact>
              <ode>
                <soft_cfm>0</soft_cfm>
                <soft_erp>0.2</soft_erp>
                <kp>1e+12</kp>
                <kd>1</kd>
                <max_vel>100</max_vel>
                <min_depth>0.001</min_depth>
              </ode>
            </contact>
          </surface>
          <max_contacts>10</max_contacts>
        </collision>
        <visual name='visual_sph_caster_front'>
          <pose>0.042 0 0.0025 0 -0 0</pose>
          <geometry>
            <sphere>
              <radius>0.002</radius>
            </sphere>
          </geometry>
        </visual>
        <collision name='collision_cyl_caster_front'>
          <pose>0.042 0 0.0065 0 -0 0</pose>
          <geometry>
            <cylinder>
              <radius>0.003</radius>
              <length>0.007</length>
            </cylinder>
          </geometry>
          <surface>
            <friction>
              <ode>
                <mu>0</mu>
                <mu2>0</mu2>
              </ode>
              <bullet>
                <friction>0</friction>
                <friction2>0</friction2>
              </bullet>
            </friction>
            <contact>
              <collide_without_contact>0</collide_without_contact>
              <ode/>
            </contact>
            <bounce/>
          </surface>
          <max_contacts>10</max_contacts>
        </collision>
        <visual name='visual_cyl_caster_front'>
          <pose>0.042 0 0.0065 0 -0 0</pose>
          <geometry>
            <cylinder>
              <radius>0.003</radius>
              <length>0.007</length>
            </cylinder>
          </geometry>
        </visual>
        <collision name='collision_sph_caster_back'>
          <pose>-0.042 0 0.0025 0 -0 0</pose>
          <geometry>
            <sphere>
              <radius>0.002</radius>
            </sphere>
          </geometry>
          <surface>
            <friction>
              <ode>
                <mu>0.01</mu>
                <mu2>0.01</mu2>
                <fdir1>0 0 0</fdir1>
                <slip1>0</slip1>
                <slip2>0</slip2>
              </ode>
            </friction>
            <bounce>
              <restitution_coefficient>0</restitution_coefficient>
              <threshold>100000</threshold>
            </bounce>
            <contact>
              <ode>
                <soft_cfm>0</soft_cfm>
                <soft_erp>0.2</soft_erp>
                <kp>1e+12</kp>
                <kd>1</kd>
                <max_vel>100</max_vel>
                <min_depth>0.001</min_depth>
              </ode>
            </contact>
          </surface>
          <max_contacts>10</max_contacts>
        </collision>
        <visual name='visual_sph_caster_back'>
          <pose>-0.042 0 0.0025 0 -0 0</pose>
          <geometry>
            <sphere>
              <radius>0.002</radius>
            </sphere>
          </geometry>
        </visual>
        <collision name='collision_cyl_caster_back'>
          <pose>-0.042 0 0.0065 0 -0 0</pose>
          <geometry>
            <cylinder>
              <radius>0.003</radius>
              <length>0.007</length>
            </cylinder>
          </geometry>
          <max_contacts>10</max_contacts>
          <surface>
            <contact>
              <ode/>
            </contact>
            <bounce/>
            <friction>
              <ode/>
            </friction>
          </surface>
        </collision>
        <visual name='visual_cyl_caster_back'>
          <pose>-0.042 0 0.0065 0 -0 0</pose>
          <geometry>
            <cylinder>
              <radius>0.003</radius>
              <length>0.007</length>
            </cylinder>
          </geometry>
        </visual>
        <pose>0 0 0 0 -0 0</pose>
        <self_collide>0</self_collide>
        <kinematic>0</kinematic>
        <gravity>1</gravity>
      </link>
      <link name='AMiRo::left_wheel'>
        <pose>0 0.035 0.03 -5.76279e-13 1.5707 1.5707</pose>
        <inertial>
          <mass>0.02</mass>
          <inertia>
            <ixx>6.8453e-06</ixx>
            <ixy>0</ixy>
            <ixz>0</ixz>
            <iyy>6.8453e-06</iyy>
            <iyz>0</iyz>
            <izz>7.5625e-06</izz>
          </inertia>
        </inertial>
        <collision name='collision'>
          <geometry>
            <cylinder>
              <radius>0.03</radius>
              <length>0.006</length>
            </cylinder>
          </geometry>
          <max_contacts>10</max_contacts>
          <surface>
            <contact>
              <ode/>
            </contact>
            <bounce/>
            <friction>
              <ode/>
            </friction>
          </surface>
        </collision>
        <visual name='visual'>
          <geometry>
            <cylinder>
              <radius>0.03</radius>
              <length>0.006</length>
            </cylinder>
          </geometry>
        </visual>
        <velocity_decay>
          <linear>0</linear>
          <angular>0</angular>
        </velocity_decay>
        <self_collide>0</self_collide>
        <kinematic>0</kinematic>
        <gravity>1</gravity>
      </link>
      <link name='AMiRo::right_wheel'>
        <pose>0 -0.035 0.03 -5.76279e-13 1.5707 1.5707</pose>
        <inertial>
          <mass>0.02</mass>
          <inertia>
            <ixx>6.8453e-06</ixx>
            <ixy>0</ixy>
            <ixz>0</ixz>
            <iyy>6.8453e-06</iyy>
            <iyz>0</iyz>
            <izz>7.5625e-06</izz>
          </inertia>
        </inertial>
        <collision name='collision'>
          <geometry>
            <cylinder>
              <radius>0.03</radius>
              <length>0.006</length>
            </cylinder>
          </geometry>
          <max_contacts>10</max_contacts>
          <surface>
            <contact>
              <ode/>
            </contact>
            <bounce/>
            <friction>
              <ode/>
            </friction>
          </surface>
        </collision>
        <visual name='visual'>
          <geometry>
            <cylinder>
              <radius>0.03</radius>
              <length>0.006</length>
            </cylinder>
          </geometry>
        </visual>
        <velocity_decay>
          <linear>0</linear>
          <angular>0</angular>
        </velocity_decay>
        <self_collide>0</self_collide>
        <kinematic>0</kinematic>
        <gravity>1</gravity>
      </link>
      <joint name='AMiRo::left_wheel_hinge' type='revolute'>
        <pose>0 0 0 0 -0 0</pose>
        <child>AMiRo::left_wheel</child>
        <parent>AMiRo::chassis</parent>
        <axis>
          <xyz>0 1 0</xyz>
          <use_parent_model_frame>1</use_parent_model_frame>
          <limit>
            <lower>-1e+16</lower>
            <upper>1e+16</upper>
          </limit>
          <dynamics>
            <spring_reference>0</spring_reference>
            <spring_stiffness>0</spring_stiffness>
          </dynamics>
        </axis>
      </joint>
      <joint name='AMiRo::right_wheel_hinge' type='revolute'>
        <pose>0 0 0 0 -0 0</pose>
        <child>AMiRo::right_wheel</child>
        <parent>AMiRo::chassis</parent>
        <axis>
          <xyz>0 1 0</xyz>
          <use_parent_model_frame>1</use_parent_model_frame>
          <limit>
            <lower>-1e+16</lower>
            <upper>1e+16</upper>
          </limit>
          <dynamics>
            <spring_reference>0</spring_reference>
            <spring_stiffness>0</spring_stiffness>
          </dynamics>
        </axis>
      </joint>
      <plugin name='model_push' filename='libgazebo_rsb_wheel.so'>
        <differentialKinematicSubscope>diffKin</differentialKinematicSubscope>
        <baseWidth>0.06</baseWidth>
        <wheelRadius>0.03</wheelRadius>
        <rightWheelMaxForceN>2.4</rightWheelMaxForceN>
        <leftWheelMaxForceN>2.4</leftWheelMaxForceN>
      </plugin>
      <link name='AMiRo::gps'>
        <sensor name='positioning' type='AMiRo::gps'>
          <pose>0 0 0 0 -0 0</pose>
          <always_on>1</always_on>
          <update_rate>1</update_rate>
          <visualize>1</visualize>
        </sensor>
        <velocity_decay>
          <linear>0</linear>
          <angular>0</angular>
        </velocity_decay>
        <pose>0 0 0 0 -0 0</pose>
        <self_collide>0</self_collide>
        <inertial>
          <inertia>
            <ixx>1</ixx>
            <ixy>0</ixy>
            <ixz>0</ixz>
            <iyy>1</iyy>
            <iyz>0</iyz>
            <izz>1</izz>
          </inertia>
          <mass>1</mass>
        </inertial>
        <kinematic>0</kinematic>
        <gravity>1</gravity>
      </link>
      <plugin name='positioning' filename='libgazebo_rsb_gps.so'>
        <alwaysOn>true</alwaysOn>
        <updateRate>10.0</updateRate>
        <gpsSubscope>AMiRo::gps</gpsSubscope>
      </plugin>
      <plugin name='odometry' filename='libgazebo_rsb_odom_amiro.so'>
        <alwaysOn>true</alwaysOn>
        <updateRate>10.0</updateRate>
        <odomSubscope>odom</odomSubscope>
        <baseWidth>0.055</baseWidth>
        <kl>0.01</kl>
        <kr>0.01</kr>
      </plugin>
      <link name='hokuyoCLAAS::link'>
        <inertial>
          <mass>0.1</mass>
          <inertia>
            <ixx>4.56e-05</ixx>
            <ixy>0</ixy>
            <ixz>0</ixz>
            <iyy>4.56e-05</iyy>
            <iyz>0</iyz>
            <izz>3.12e-05</izz>
          </inertia>
        </inertial>
        <visual name='visual'>
          <geometry>
            <mesh>
              <uri>model://hokuyo/meshes/hokuyo.dae</uri>
            </mesh>
          </geometry>
        </visual>
        <collision name='collision-base'>
          <pose>0 0 -0.0145 0 -0 0</pose>
          <geometry>
            <box>
              <size>0.05 0.05 0.041</size>
            </box>
          </geometry>
          <max_contacts>10</max_contacts>
          <surface>
            <contact>
              <ode/>
            </contact>
            <bounce/>
            <friction>
              <ode/>
            </friction>
          </surface>
        </collision>
        <collision name='collision-top'>
          <pose>0 0 0.0205 0 -0 0</pose>
          <geometry>
            <cylinder>
              <radius>0.021</radius>
              <length>0.029</length>
            </cylinder>
          </geometry>
          <max_contacts>10</max_contacts>
          <surface>
            <contact>
              <ode/>
            </contact>
            <bounce/>
            <friction>
              <ode/>
            </friction>
          </surface>
        </collision>
        <sensor name='laser' type='ray'>
          <pose>0.01 0 0.0175 0 -0 0</pose>
          <ray>
            <scan>
              <horizontal>
                <samples>51</samples>
                <resolution>1</resolution>
                <min_angle>-0.707</min_angle>
                <max_angle>0.707</max_angle>
              </horizontal>
            </scan>
            <range>
              <min>0.03</min>
              <max>5</max>
              <resolution>0.01</resolution>
            </range>
            <noise>
              <type>gaussian</type>
              <mean>0</mean>
              <stddev>0</stddev>
            </noise>
          </ray>
          <plugin name='laser' filename='libgazebo_rsb_laser_inversemodel_edge.so'>
            <lidarSubscope>lidar</lidarSubscope>
          </plugin>
          <always_on>1</always_on>
          <update_rate>10</update_rate>
          <visualize>1</visualize>
        </sensor>
        <velocity_decay>
          <linear>0</linear>
          <angular>0</angular>
        </velocity_decay>
        <pose>0 0 0.118 0 0.707 0</pose>
        <self_collide>0</self_collide>
        <kinematic>0</kinematic>
        <gravity>1</gravity>
      </link>
      <joint name='hokuyo_joint' type='revolute'>
        <child>hokuyoCLAAS::link</child>
        <parent>AMiRo::chassis</parent>
        <axis>
          <xyz>0 0 1</xyz>
          <limit>
            <upper>0</upper>
            <lower>0</lower>
          </limit>
          <use_parent_model_frame>1</use_parent_model_frame>
          <dynamics>
            <spring_reference>0</spring_reference>
            <spring_stiffness>0</spring_stiffness>
          </dynamics>
        </axis>
      </joint>
      <pose>-1 -1 0 0 -0 0</pose>
    </model>
    <model name='unit_box_crop'>
      <static>1</static>
      <pose>-2 -1 0.5 0 -0 0</pose>
      <link name='link'>
        <inertial>
          <mass>1</mass>
          <inertia>
            <ixx>1</ixx>
            <ixy>0</ixy>
            <ixz>0</ixz>
            <iyy>1</iyy>
            <iyz>0</iyz>
            <izz>1</izz>
          </inertia>
        </inertial>
        <collision name='collision'>
          <geometry>
            <box>
              <size>1 1.0053 0.061382</size>
            </box>
          </geometry>
          <max_contacts>10</max_contacts>
          <surface>
            <contact>
              <ode/>
              <collide_without_contact>1</collide_without_contact>
              <collide_without_contact_bitmask>12</collide_without_contact_bitmask>
            </contact>
            <bounce/>
            <friction>
              <ode/>
            </friction>
          </surface>
        </collision>
        <visual name='visual'>
          <geometry>
            <box>
              <size>1 1.0053 0.061382</size>
            </box>
          </geometry>
          <material>
            <script>
              <uri>file://media/materials/scripts/gazebo.material</uri>
              <name>Gazebo/Yellow</name>
            </script>
          </material>
        </visual>
        <velocity_decay>
          <linear>0</linear>
          <angular>0</angular>
        </velocity_decay>
        <self_collide>0</self_collide>
        <kinematic>1</kinematic>
        <gravity>1</gravity>
      </link>
    </model>
    <state world_name='default'>
      <sim_time>2763 510000000</sim_time>
      <real_time>30 510162971</real_time>
      <wall_time>1424444394 508848034</wall_time>
      <model name='AMiRo Hokuyo Pitch_9'>
        <pose>-0.417339 -0.419104 -1e-06 2.2e-05 -0.000173 0.003479</pose>
        <link name='AMiRo::chassis'>
          <pose>-0.417339 -0.419104 -1e-06 2.2e-05 -0.000173 0.003479</pose>
          <velocity>0 9.5e-05 -0.00079 0.020412 0.000117 2.8e-05</velocity>
          <acceleration>-0.003693 1.05635 -2.78783 0.17365 0.000607 0.001039</acceleration>
          <wrench>-0.001477 0.422541 -1.11513 0 -0 0</wrench>
        </link>
        <link name='AMiRo::gps'>
          <pose>-0.417338 -0.423011 -4524.07 -4e-06 0.000222 0.003467</pose>
          <velocity>0 0 -297.773 0 -0 0</velocity>
          <acceleration>0 0 -9.8 0 -0 0</acceleration>
          <wrench>0 0 -9.8 0 -0 0</wrench>
        </link>
        <link name='AMiRo::left_wheel'>
          <pose>-0.417466 -0.384107 0.03 -1.71231 1.57064 -0.13813</pose>
          <velocity>3e-06 -0.000563 9.7e-05 0.019375 0.0001 2.5e-05</velocity>
          <acceleration>0.001688 -1.01683 0.142506 0.011778 1.8e-05 2.8e-05</acceleration>
          <wrench>3.4e-05 -0.020337 0.00285 0 -0 0</wrench>
        </link>
        <link name='AMiRo::right_wheel'>
          <pose>-0.417223 -0.454104 0.029999 -1.1503 1.5704 0.423883</pose>
          <velocity>5e-06 -0.000646 -0.001651 0.009506 7.9e-05 2.7e-05</velocity>
          <acceleration>0.006139 -1.08389 -5.60998 0.008482 4.2e-05 3e-05</acceleration>
          <wrench>0.000123 -0.021678 -0.1122 0 -0 0</wrench>
        </link>
        <link name='hokuyoCLAAS::link'>
          <pose>-0.41736 -0.419107 0.117999 3e-05 0.706827 0.003498</pose>
          <velocity>1.4e-05 -0.002286 -0.000791 0.020159 0.000116 0.000149</velocity>
          <acceleration>0.01973 -5.63986 -2.79493 0.025821 9.1e-05 8.1e-05</acceleration>
          <wrench>0.001973 -0.563986 -0.279493 0 -0 0</wrench>
        </link>
      </model>
      <model name='ground_plane'>
        <pose>0 0 0 0 -0 0</pose>
        <link name='link'>
          <pose>0 0 0 0 -0 0</pose>
          <velocity>0 0 0 0 -0 0</velocity>
          <acceleration>0 0 0 0 -0 0</acceleration>
          <wrench>0 0 0 0 -0 0</wrench>
        </link>
      </model>
      <model name='unit_box_crop'>
        <pose>0.152326 0.034073 0.015953 -9e-06 -0 0.020798</pose>
        <link name='link'>
          <pose>0.152326 0.034073 0.015953 -9e-06 -0 0.020798</pose>
          <velocity>0 0 0 0 -0 0</velocity>
          <acceleration>0 0 0 0 -0 0</acceleration>
          <wrench>0 0 0 0 -0 0</wrench>
        </link>
      </model>
      <model name='unit_box_weed'>
        <pose>-0.02263 -0.425116 0.015943 -9e-06 -0 0.020798</pose>
        <link name='link'>
          <pose>-0.02263 -0.425116 0.015943 -9e-06 -0 0.020798</pose>
          <velocity>0 0 0 0 -0 0</velocity>
          <acceleration>0 0 0 0 -0 0</acceleration>
          <wrench>0 0 0 0 -0 0</wrench>
        </link>
      </model>
    </state>
    <gui fullscreen='0'>
      <camera name='user_camera'>
        <pose>-0.170952 -1.54893 0.561098 -3.18319e-17 0.511643 1.58419</pose>
        <view_controller>orbit</view_controller>
      </camera>
    </gui>
    <model name='unit_box_weed'>
      <static>1</static>
      <pose>0 -1.51305 0.015953 -9e-06 -0 0.020798</pose>
      <link name='link'>
        <inertial>
          <mass>1</mass>
          <inertia>
            <ixx>1</ixx>
            <ixy>0</ixy>
            <ixz>0</ixz>
            <iyy>1</iyy>
            <iyz>0</iyz>
            <izz>1</izz>
          </inertia>
        </inertial>
        <collision name='collision'>
          <geometry>
            <box>
              <size>0.042695 0.060995 0.082661</size>
            </box>
          </geometry>
          <max_contacts>10</max_contacts>
          <surface>
            <contact>
              <ode/>
              <collide_without_contact>1</collide_without_contact>
              <collide_without_contact_bitmask>12</collide_without_contact_bitmask>
            </contact>
            <bounce/>
            <friction>
              <ode/>
            </friction>
          </surface>
        </collision>
        <visual name='visual'>
          <geometry>
            <box>
              <size>0.042695 0.060674 0.082661</size>
            </box>
          </geometry>
          <material>
            <script>
              <uri>file://media/materials/scripts/gazebo.material</uri>
              <name>Gazebo/Green</name>
            </script>
          </material>
        </visual>
        <velocity_decay>
          <linear>0</linear>
          <angular>0</angular>
        </velocity_decay>
        <self_collide>0</self_collide>
        <kinematic>1</kinematic>
        <gravity>1</gravity>
      </link>
    </model>
  </world>
</sdf>
